{
 "cells": [
  {
   "cell_type": "code",
   "execution_count": 18,
   "metadata": {},
   "outputs": [
    {
     "name": "stdout",
     "output_type": "stream",
     "text": [
      "The autoreload extension is already loaded. To reload it, use:\n",
      "  %reload_ext autoreload\n"
     ]
    },
    {
     "data": {
      "text/plain": [
       "Profile<uuid='155a05c5c8f7420aa49bbf9207908698' name='supercon'>"
      ]
     },
     "execution_count": 18,
     "metadata": {},
     "output_type": "execute_result"
    }
   ],
   "source": [
    "%load_ext autoreload\n",
    "%autoreload 2\n",
    "\n",
    "from aiida import orm, engine, load_profile\n",
    "from aiida.common import NotExistent\n",
    "\n",
    "import aiida_dislocation\n",
    "import importlib\n",
    "# importlib.reload(aiida_dislocation.workflows.usf)\n",
    "from aiida_dislocation.workflows.usf import USFWorkChain\n",
    "\n",
    "from ase.io import read\n",
    "from ase.build import bulk\n",
    "from aiida.engine import run\n",
    "\n",
    "import logging\n",
    "\n",
    "\n",
    "load_profile()"
   ]
  },
  {
   "cell_type": "code",
   "execution_count": 19,
   "metadata": {},
   "outputs": [
    {
     "name": "stdout",
     "output_type": "stream",
     "text": [
      "Group 'test/workchains/USF/' already exists.\n"
     ]
    }
   ],
   "source": [
    "\n",
    "\n",
    "group_label = 'test/workchains/USF/'\n",
    "test_USF_group, created = orm.Group.collection.get_or_create(label=group_label)\n",
    "if created:\n",
    "    print(f\"Group '{group_label}' created.\")\n",
    "else:\n",
    "    print(f\"Group '{group_label}' already exists.\")\n",
    "\n",
    "\n",
    "computer = 'lucia'\n",
    "lucia_computer = orm.load_computer(computer)\n",
    "lucia_computer.set_workdir('/gpfs/scratch/acad/elph/yimzhang/aiida_workdir/test_aiida_dislocation')\n",
    "\n",
    "version = '741'\n",
    "code = 'pw'\n",
    "label = 'qe-741-pw'\n",
    "bin_dir = '/gpfs/scratch/acad/elph/yimzhang/apps/q-e-qe-7.4.1/bin/'\n",
    "try:\n",
    "    orm.load_code(f'{label}@{computer}')\n",
    "except NotExistent as exc:\n",
    "    orm.InstalledCode(\n",
    "        label=label,\n",
    "        description=f'Quantum ESPRESSO {version} version for {code}.x',\n",
    "        computer=lucia_computer,\n",
    "        filepath_executable=f'{bin_dir}/{code}.x',\n",
    "        default_calc_job_plugin=f'quantumespresso.{code}',\n",
    "    ).store()\n",
    "\n",
    "pw_label = f'qe-{version}-pw'\n",
    "pw_code = orm.load_code(f'{pw_label}@{computer}')\n"
   ]
  },
  {
   "cell_type": "code",
   "execution_count": 20,
   "metadata": {},
   "outputs": [
    {
     "data": {
      "text/plain": [
       "{'port': 22,\n",
       " 'gss_kex': False,\n",
       " 'timeout': 60,\n",
       " 'compress': True,\n",
       " 'gss_auth': False,\n",
       " 'gss_host': 'frontal.lucia.cenaero.be',\n",
       " 'username': 'yimzhang',\n",
       " 'key_policy': 'AutoAddPolicy',\n",
       " 'proxy_jump': 'gwceci.cism.ucl.ac.be',\n",
       " 'allow_agent': True,\n",
       " 'key_filename': '/home/ucl/modl/yimzhang/.ssh/id_rsa.ceci',\n",
       " 'look_for_keys': True,\n",
       " 'proxy_command': '',\n",
       " 'safe_interval': 30.0,\n",
       " 'gss_deleg_creds': False,\n",
       " 'use_login_shell': False,\n",
       " 'load_system_host_keys': True}"
      ]
     },
     "execution_count": 20,
     "metadata": {},
     "output_type": "execute_result"
    }
   ],
   "source": [
    "lucia_computer.get_configuration()"
   ]
  },
  {
   "cell_type": "code",
   "execution_count": null,
   "metadata": {},
   "outputs": [
    {
     "name": "stdout",
     "output_type": "stream",
     "text": [
      "Agent pid 956771\n"
     ]
    },
    {
     "name": "stderr",
     "output_type": "stream",
     "text": [
      "ssh_askpass: exec(/usr/libexec/openssh/ssh-askpass): No such file or directory\n"
     ]
    },
    {
     "name": "stdout",
     "output_type": "stream",
     "text": [
      "SSH_AUTH_SOCK=/tmp/ssh-P3kPJSlw2OWF/agent.956770\n"
     ]
    },
    {
     "name": "stderr",
     "output_type": "stream",
     "text": [
      "ssh: connect to host gwceci.cism.ucl.ac.be port 22: Connection refused\n",
      "kex_exchange_identification: Connection closed by remote host\n"
     ]
    },
    {
     "ename": "CalledProcessError",
     "evalue": "Command 'b'\\neval \"$(ssh-agent -s)\"\\nssh-add ~/.ssh/id_rsa.ceci\\necho \"SSH_AUTH_SOCK=$SSH_AUTH_SOCK\"\\nssh -o ProxyJump=gwceci.cism.ucl.ac.be -o BatchMode=yes yimzhang@frontal.lucia.cenaero.be hostname\\n'' returned non-zero exit status 255.",
     "output_type": "error",
     "traceback": [
      "\u001b[31m---------------------------------------------------------------------------\u001b[39m",
      "\u001b[31mCalledProcessError\u001b[39m                        Traceback (most recent call last)",
      "\u001b[36mCell\u001b[39m\u001b[36m \u001b[39m\u001b[32mIn[27]\u001b[39m\u001b[32m, line 1\u001b[39m\n\u001b[32m----> \u001b[39m\u001b[32m1\u001b[39m \u001b[43mget_ipython\u001b[49m\u001b[43m(\u001b[49m\u001b[43m)\u001b[49m\u001b[43m.\u001b[49m\u001b[43mrun_cell_magic\u001b[49m\u001b[43m(\u001b[49m\u001b[33;43m'\u001b[39;49m\u001b[33;43mbash\u001b[39;49m\u001b[33;43m'\u001b[39;49m\u001b[43m,\u001b[49m\u001b[43m \u001b[49m\u001b[33;43m'\u001b[39;49m\u001b[33;43m'\u001b[39;49m\u001b[43m,\u001b[49m\u001b[43m \u001b[49m\u001b[33;43m'\u001b[39;49m\u001b[38;5;130;43;01m\\n\u001b[39;49;00m\u001b[33;43meval \u001b[39;49m\u001b[33;43m\"\u001b[39;49m\u001b[33;43m$(ssh-agent -s)\u001b[39;49m\u001b[33;43m\"\u001b[39;49m\u001b[38;5;130;43;01m\\n\u001b[39;49;00m\u001b[33;43mssh-add ~/.ssh/id_rsa.ceci\u001b[39;49m\u001b[38;5;130;43;01m\\n\u001b[39;49;00m\u001b[33;43mecho \u001b[39;49m\u001b[33;43m\"\u001b[39;49m\u001b[33;43mSSH_AUTH_SOCK=$SSH_AUTH_SOCK\u001b[39;49m\u001b[33;43m\"\u001b[39;49m\u001b[38;5;130;43;01m\\n\u001b[39;49;00m\u001b[33;43mssh -o ProxyJump=gwceci.cism.ucl.ac.be -o BatchMode=yes yimzhang@frontal.lucia.cenaero.be hostname\u001b[39;49m\u001b[38;5;130;43;01m\\n\u001b[39;49;00m\u001b[33;43m'\u001b[39;49m\u001b[43m)\u001b[49m\n",
      "\u001b[36mFile \u001b[39m\u001b[32m~/miniforge3/envs/aiida-240/lib/python3.11/site-packages/IPython/core/interactiveshell.py:2542\u001b[39m, in \u001b[36mInteractiveShell.run_cell_magic\u001b[39m\u001b[34m(self, magic_name, line, cell)\u001b[39m\n\u001b[32m   2540\u001b[39m \u001b[38;5;28;01mwith\u001b[39;00m \u001b[38;5;28mself\u001b[39m.builtin_trap:\n\u001b[32m   2541\u001b[39m     args = (magic_arg_s, cell)\n\u001b[32m-> \u001b[39m\u001b[32m2542\u001b[39m     result = \u001b[43mfn\u001b[49m\u001b[43m(\u001b[49m\u001b[43m*\u001b[49m\u001b[43margs\u001b[49m\u001b[43m,\u001b[49m\u001b[43m \u001b[49m\u001b[43m*\u001b[49m\u001b[43m*\u001b[49m\u001b[43mkwargs\u001b[49m\u001b[43m)\u001b[49m\n\u001b[32m   2544\u001b[39m \u001b[38;5;66;03m# The code below prevents the output from being displayed\u001b[39;00m\n\u001b[32m   2545\u001b[39m \u001b[38;5;66;03m# when using magics with decorator @output_can_be_silenced\u001b[39;00m\n\u001b[32m   2546\u001b[39m \u001b[38;5;66;03m# when the last Python token in the expression is a ';'.\u001b[39;00m\n\u001b[32m   2547\u001b[39m \u001b[38;5;28;01mif\u001b[39;00m \u001b[38;5;28mgetattr\u001b[39m(fn, magic.MAGIC_OUTPUT_CAN_BE_SILENCED, \u001b[38;5;28;01mFalse\u001b[39;00m):\n",
      "\u001b[36mFile \u001b[39m\u001b[32m~/miniforge3/envs/aiida-240/lib/python3.11/site-packages/IPython/core/magics/script.py:159\u001b[39m, in \u001b[36mScriptMagics._make_script_magic.<locals>.named_script_magic\u001b[39m\u001b[34m(line, cell)\u001b[39m\n\u001b[32m    157\u001b[39m \u001b[38;5;28;01melse\u001b[39;00m:\n\u001b[32m    158\u001b[39m     line = script\n\u001b[32m--> \u001b[39m\u001b[32m159\u001b[39m \u001b[38;5;28;01mreturn\u001b[39;00m \u001b[38;5;28;43mself\u001b[39;49m\u001b[43m.\u001b[49m\u001b[43mshebang\u001b[49m\u001b[43m(\u001b[49m\u001b[43mline\u001b[49m\u001b[43m,\u001b[49m\u001b[43m \u001b[49m\u001b[43mcell\u001b[49m\u001b[43m)\u001b[49m\n",
      "\u001b[36mFile \u001b[39m\u001b[32m~/miniforge3/envs/aiida-240/lib/python3.11/site-packages/IPython/core/magics/script.py:336\u001b[39m, in \u001b[36mScriptMagics.shebang\u001b[39m\u001b[34m(self, line, cell)\u001b[39m\n\u001b[32m    331\u001b[39m \u001b[38;5;28;01mif\u001b[39;00m args.raise_error \u001b[38;5;129;01mand\u001b[39;00m p.returncode != \u001b[32m0\u001b[39m:\n\u001b[32m    332\u001b[39m     \u001b[38;5;66;03m# If we get here and p.returncode is still None, we must have\u001b[39;00m\n\u001b[32m    333\u001b[39m     \u001b[38;5;66;03m# killed it but not yet seen its return code. We don't wait for it,\u001b[39;00m\n\u001b[32m    334\u001b[39m     \u001b[38;5;66;03m# in case it's stuck in uninterruptible sleep. -9 = SIGKILL\u001b[39;00m\n\u001b[32m    335\u001b[39m     rc = p.returncode \u001b[38;5;129;01mor\u001b[39;00m -\u001b[32m9\u001b[39m\n\u001b[32m--> \u001b[39m\u001b[32m336\u001b[39m     \u001b[38;5;28;01mraise\u001b[39;00m CalledProcessError(rc, cell)\n",
      "\u001b[31mCalledProcessError\u001b[39m: Command 'b'\\neval \"$(ssh-agent -s)\"\\nssh-add ~/.ssh/id_rsa.ceci\\necho \"SSH_AUTH_SOCK=$SSH_AUTH_SOCK\"\\nssh -o ProxyJump=gwceci.cism.ucl.ac.be -o BatchMode=yes yimzhang@frontal.lucia.cenaero.be hostname\\n'' returned non-zero exit status 255."
     ]
    },
    {
     "name": "stderr",
     "output_type": "stream",
     "text": [
      "04/28/2025 03:35:23 PM <885922> aiida.transport.SshTransport: [ERROR] Error connecting to proxy 'gwceci.cism.ucl.ac.be' through SSH: [SshTransport] [Errno None] Unable to connect to port 22 on 130.104.1.234, connect_args were: {'username': 'yimzhang', 'port': 22, 'look_for_keys': True, 'key_filename': '/home/ucl/modl/yimzhang/.ssh/id_rsa.ceci', 'timeout': 60, 'allow_agent': True, 'compress': True, 'gss_auth': False, 'gss_kex': False, 'gss_deleg_creds': False, 'gss_host': 'frontal.lucia.cenaero.be'}\n",
      "04/28/2025 03:35:23 PM <885922> aiida.engine.transports: [ERROR] exception occurred while trying to open transport:\n",
      " [Errno None] Unable to connect to port 22 on 130.104.1.234\n"
     ]
    }
   ],
   "source": [
    "%%bash\n",
    "\n",
    "eval \"$(ssh-agent -s)\"\n",
    "ssh-add ~/.ssh/id_rsa.ceci\n",
    "echo \"SSH_AUTH_SOCK=$SSH_AUTH_SOCK\"\n",
    "ssh -o ProxyJump=gwceci.cism.ucl.ac.be -o BatchMode=yes yimzhang@frontal.lucia.cenaero.be hostname\n"
   ]
  },
  {
   "cell_type": "markdown",
   "metadata": {},
   "source": [
    "# TEST A1 -- Aluminium"
   ]
  },
  {
   "cell_type": "code",
   "execution_count": 12,
   "metadata": {},
   "outputs": [],
   "source": [
    "import yaml\n",
    "\n",
    "ase_atom = read('./structures/cif/Al-225-A1.cif', format='cif')\n",
    "structure = orm.StructureData(ase=ase_atom)\n",
    "\n",
    "pseudo_family = orm.load_group('PseudoDojo/0.5/PBE/SR/standard/upf')\n",
    "\n",
    "pseudos = pseudo_family.get_pseudos(structure=structure)\n",
    "\n",
    "cutoff_wfc, cutoff_rho = pseudo_family.get_recommended_cutoffs(\n",
    "    structure=structure,\n",
    "    unit='Ry'\n",
    ")\n",
    "\n",
    "kpoints = orm.KpointsData()\n",
    "kpoints.set_kpoints_mesh([12, 12, 12])\n",
    "\n",
    "settings = orm.Dict({\n",
    "    # 'cmdline': ['-npool', '2']\n",
    "})\n",
    "\n",
    "usf_overrides_yaml = open('./usf.yaml')\n",
    "usf_overrides = yaml.safe_load(usf_overrides_yaml)\n",
    "\n",
    "inputs = {}\n",
    "\n",
    "inputs['metadata'] = usf_overrides.get('metadata', {})\n",
    "inputs['structure'] = structure\n",
    "inputs['kpoints'] = kpoints\n",
    "inputs['pw'] = usf_overrides.get('pw', {})\n",
    "inputs['pw']['pseudos'] = pseudos\n",
    "inputs['pw']['code'] = pw_code\n",
    "inputs['pw']['parameters']['CONTROL']['disk_io'] = 'nowf'\n",
    "inputs['pw']['parameters']['SYSTEM']['degauss'] = 0.02\n",
    "inputs['pw']['parameters']['ELECTRONS']['conv_thr'] = 1e-5\n"
   ]
  },
  {
   "cell_type": "markdown",
   "metadata": {},
   "source": [
    "## {100} surface"
   ]
  },
  {
   "cell_type": "code",
   "execution_count": 13,
   "metadata": {},
   "outputs": [
    {
     "name": "stderr",
     "output_type": "stream",
     "text": [
      "04/28/2025 10:17:46 AM <158968> aiida.orm.nodes.process.workflow.workchain.WorkChainNode: [REPORT] [71643|USFWorkChain|validate_slipping_system]: FCC element crystal <space group #225, prototype Cu>. Usually, the gliding plane is 111.\n",
      "04/28/2025 10:17:46 AM <158968> aiida.orm.nodes.process.workflow.workchain.WorkChainNode: [REPORT] [71643|USFWorkChain|validate_slipping_system]: Now we are working on 100 gliding plane.\n",
      "04/28/2025 10:17:46 AM <158968> aiida.orm.nodes.process.workflow.workchain.WorkChainNode: [REPORT] [71643|USFWorkChain|validate_slipping_system]: Faulting is possible for 100 gliding plane.The stacking order is AB.Slipping direction: None. \n",
      "04/28/2025 10:17:47 AM <158968> aiida.orm.nodes.process.workflow.workchain.WorkChainNode: [REPORT] [71643|USFWorkChain|run_scf]: launching PwCalculation<71644> for Al unit cell geometry.\n",
      "04/28/2025 10:21:26 AM <158968> aiida.orm.nodes.process.workflow.workchain.WorkChainNode: [REPORT] [71643|USFWorkChain|inspect_scf]: SCF calculation<71644> finished\n",
      "04/28/2025 10:21:26 AM <158968> aiida.orm.nodes.process.workflow.workchain.WorkChainNode: [REPORT] [71643|USFWorkChain|run_USF]: Multiplicity of the faulted geometry: 8\n",
      "04/28/2025 10:21:26 AM <158968> aiida.orm.nodes.process.workflow.workchain.WorkChainNode: [REPORT] [71643|USFWorkChain|run_USF]: launching PwCalculation<71652> for USF geometry.\n",
      "04/28/2025 10:25:51 AM <158968> aiida.orm.nodes.process.workflow.workchain.WorkChainNode: [REPORT] [71643|USFWorkChain|inspect_USF]: SCF calculation<71652> for USF geometry finished\n",
      "04/28/2025 10:25:51 AM <158968> aiida.orm.nodes.process.workflow.workchain.WorkChainNode: [REPORT] [71643|USFWorkChain|results]: Energy difference per surface area: uuid: 3a96df45-7535-43ba-8436-3de47bf5ea7d (unstored) value: 110.44963489182699 J/m^2\n",
      "04/28/2025 10:25:51 AM <158968> aiida.orm.nodes.process.workflow.workchain.WorkChainNode: [REPORT] [71643|USFWorkChain|results]: Results\n",
      "04/28/2025 10:25:51 AM <158968> aiida.orm.nodes.process.workflow.workchain.WorkChainNode: [REPORT] [71643|USFWorkChain|on_terminated]: remote folders will not be cleaned\n"
     ]
    }
   ],
   "source": [
    "inputs['skip_uc'] = orm.Bool(False)\n",
    "inputs['n_layers'] =orm.Int(8)\n",
    "inputs['slipping_system'] = orm.List(['A1', '100'])\n",
    "\n",
    "logging.getLogger('aiida.transport.SshTransport').setLevel(logging.ERROR)\n",
    "logging.getLogger('aiida.scheduler.slurm').setLevel(logging.ERROR)\n",
    "\n",
    "test_node = run.get_node(USFWorkChain, **inputs)\n",
    "test_USF_group.add_nodes(test_node.node)"
   ]
  },
  {
   "cell_type": "markdown",
   "metadata": {},
   "source": [
    "## {110} surface"
   ]
  },
  {
   "cell_type": "code",
   "execution_count": 15,
   "metadata": {},
   "outputs": [
    {
     "name": "stderr",
     "output_type": "stream",
     "text": [
      "04/28/2025 10:40:12 AM <158968> aiida.orm.nodes.process.workflow.workchain.WorkChainNode: [REPORT] [71677|USFWorkChain|validate_slipping_system]: FCC element crystal <space group #225, prototype Cu>. Usually, the gliding plane is 111.\n",
      "04/28/2025 10:40:12 AM <158968> aiida.orm.nodes.process.workflow.workchain.WorkChainNode: [REPORT] [71677|USFWorkChain|validate_slipping_system]: Now we are working on 110 gliding plane.\n",
      "04/28/2025 10:40:12 AM <158968> aiida.orm.nodes.process.workflow.workchain.WorkChainNode: [REPORT] [71677|USFWorkChain|validate_slipping_system]: Faulting is possible for 110 gliding plane.The stacking order is AB. Slipping direction: 1/2[112]. \n",
      "04/28/2025 10:40:12 AM <158968> aiida.orm.nodes.process.workflow.workchain.WorkChainNode: [WARNING] You are skipping the unitcell calculation. Hopefully you know what you are doing!\n",
      "04/28/2025 10:40:12 AM <158968> aiida.orm.nodes.process.workflow.workchain.WorkChainNode: [REPORT] [71677|USFWorkChain|run_USF]: Multiplicity of the faulted geometry: 8\n",
      "04/28/2025 10:40:12 AM <158968> aiida.orm.nodes.process.workflow.workchain.WorkChainNode: [REPORT] [71677|USFWorkChain|run_USF]: launching PwCalculation<71680> for USF geometry.\n",
      "04/28/2025 10:41:57 AM <158968> aiida.orm.nodes.process.workflow.workchain.WorkChainNode: [REPORT] [71677|USFWorkChain|inspect_USF]: SCF calculation<71680> for USF geometry finished\n",
      "04/28/2025 10:41:57 AM <158968> aiida.orm.nodes.process.workflow.workchain.WorkChainNode: [REPORT] [71677|USFWorkChain|results]: Total energy of the faulted geometry: -474.61461166176 eV\n",
      "04/28/2025 10:41:57 AM <158968> aiida.orm.nodes.process.workflow.workchain.WorkChainNode: [REPORT] [71677|USFWorkChain|results]: Results\n",
      "04/28/2025 10:41:57 AM <158968> aiida.orm.nodes.process.workflow.workchain.WorkChainNode: [REPORT] [71677|USFWorkChain|on_terminated]: remote folders will not be cleaned\n"
     ]
    }
   ],
   "source": [
    "inputs['skip_uc'] = orm.Bool(True)\n",
    "inputs['n_layers'] =orm.Int(8)\n",
    "inputs['slipping_system'] = orm.List(['A1', '110'])\n",
    "\n",
    "logging.getLogger('aiida.transport.SshTransport') .setLevel(logging.ERROR)\n",
    "logging.getLogger('aiida.scheduler.slurm').setLevel(logging.ERROR)\n",
    "\n",
    "test_node = run.get_node(USFWorkChain, **inputs)\n",
    "test_USF_group.add_nodes(test_node.node)"
   ]
  },
  {
   "cell_type": "markdown",
   "metadata": {},
   "source": [
    "## {111} surface"
   ]
  },
  {
   "cell_type": "code",
   "execution_count": 7,
   "metadata": {},
   "outputs": [
    {
     "name": "stderr",
     "output_type": "stream",
     "text": [
      "04/28/2025 09:18:10 AM <85805> aiida.orm.nodes.process.workflow.workchain.WorkChainNode: [REPORT] [71584|USFWorkChain|validate_slipping_system]: We are doing FCC element crystal <space group #225, prototype Cu>. Usually, the gliding plane is 111.\n",
      "04/28/2025 09:18:10 AM <85805> aiida.orm.nodes.process.workflow.workchain.WorkChainNode: [REPORT] [71584|USFWorkChain|validate_slipping_system]: ABC stacking for {111} gliding plane. Faulting possible. slipping direction is along 1/2[110].\n",
      "04/28/2025 09:18:10 AM <85805> aiida.orm.nodes.process.workflow.workchain.WorkChainNode: [REPORT] [71584|USFWorkChain|run_scf]: launching PwCalculation<71585> for Al unit cell geometry.\n",
      "04/28/2025 09:21:02 AM <85805> aiida.orm.nodes.process.workflow.workchain.WorkChainNode: [REPORT] [71584|USFWorkChain|inspect_scf]: SCF calculation<71585> finished\n",
      "04/28/2025 09:21:02 AM <85805> aiida.orm.nodes.process.workflow.workchain.WorkChainNode: [REPORT] [71584|USFWorkChain|run_USF]: Multiplicity of the faulted geometry: 8\n",
      "04/28/2025 09:21:03 AM <85805> aiida.orm.nodes.process.workflow.workchain.WorkChainNode: [REPORT] [71584|USFWorkChain|run_USF]: launching PwCalculation<71593> for USF geometry.\n",
      "04/28/2025 09:24:39 AM <85805> aiida.orm.nodes.process.workflow.workchain.WorkChainNode: [REPORT] [71584|USFWorkChain|inspect_USF]: SCF calculation<71593> for USF geometry finished\n",
      "04/28/2025 09:24:40 AM <85805> aiida.orm.nodes.process.workflow.workchain.WorkChainNode: [REPORT] [71584|USFWorkChain|results]: Energy difference per surface area: uuid: 0d14f555-a8d1-4fc2-b72a-e8d4ee034bf3 (unstored) value: 5.001486018232243 J/m^2\n",
      "04/28/2025 09:24:40 AM <85805> aiida.orm.nodes.process.workflow.workchain.WorkChainNode: [REPORT] [71584|USFWorkChain|results]: Results\n",
      "04/28/2025 09:24:40 AM <85805> aiida.orm.nodes.process.workflow.workchain.WorkChainNode: [REPORT] [71584|USFWorkChain|on_terminated]: remote folders will not be cleaned\n"
     ]
    }
   ],
   "source": [
    "inputs['skip_uc'] = orm.Bool(False)\n",
    "inputs['n_layers'] =orm.Int(9)\n",
    "inputs['slipping_system'] = orm.List(['A1', '111', None])\n",
    "\n",
    "logging.getLogger('aiida.transport.SshTransport').setLevel(logging.ERROR)\n",
    "logging.getLogger('aiida.scheduler.slurm').setLevel(logging.ERROR)\n",
    "\n",
    "test_node = run.get_node(USFWorkChain, **inputs)\n",
    "test_USF_group.add_nodes(test_node.node)"
   ]
  },
  {
   "cell_type": "markdown",
   "metadata": {},
   "source": [
    "# TEST A2 -- Vanadium"
   ]
  },
  {
   "cell_type": "code",
   "execution_count": 22,
   "metadata": {},
   "outputs": [],
   "source": [
    "import yaml\n",
    "\n",
    "ase_atom = read('./structures/cif/V-227-A2.cif', format='cif')\n",
    "structure = orm.StructureData(ase=ase_atom)\n",
    "\n",
    "pseudo_family = orm.load_group('PseudoDojo/0.5/PBE/SR/standard/upf')\n",
    "\n",
    "pseudos = pseudo_family.get_pseudos(structure=structure)\n",
    "\n",
    "cutoff_wfc, cutoff_rho = pseudo_family.get_recommended_cutoffs(\n",
    "    structure=structure,\n",
    "    unit='Ry'\n",
    ")\n",
    "\n",
    "kpoints = orm.KpointsData()\n",
    "kpoints.set_kpoints_mesh([12, 12, 12])\n",
    "\n",
    "settings = orm.Dict({\n",
    "    # 'cmdline': ['-npool', '2']\n",
    "})\n",
    "\n",
    "usf_overrides_yaml = open('./usf-lucia.yaml')\n",
    "usf_overrides = yaml.safe_load(usf_overrides_yaml)\n",
    "\n",
    "inputs = {}\n",
    "\n",
    "inputs['metadata'] = usf_overrides.get('metadata', {})\n",
    "inputs['structure'] = structure\n",
    "inputs['kpoints'] = kpoints\n",
    "inputs['pw'] = usf_overrides.get('pw', {})\n",
    "inputs['pw']['pseudos'] = pseudos\n",
    "inputs['pw']['code'] = pw_code\n",
    "inputs['pw']['parameters']['CONTROL']['disk_io'] = 'nowf'\n",
    "inputs['pw']['parameters']['SYSTEM']['degauss'] = 0.01\n",
    "inputs['pw']['parameters']['ELECTRONS']['conv_thr'] = 1e-5\n",
    "\n"
   ]
  },
  {
   "cell_type": "markdown",
   "metadata": {},
   "source": [
    "## {100} surface"
   ]
  },
  {
   "cell_type": "code",
   "execution_count": 5,
   "metadata": {},
   "outputs": [
    {
     "name": "stderr",
     "output_type": "stream",
     "text": [
      "04/28/2025 03:17:04 PM <885922> aiida.orm.nodes.process.workflow.workchain.WorkChainNode: [REPORT] [71900|USFWorkChain|validate_slipping_system]: FCC element crystal <space group #227, prototype V>. I don't know the usual gliding plane. \n",
      "04/28/2025 03:17:04 PM <885922> aiida.orm.nodes.process.workflow.workchain.WorkChainNode: [REPORT] [71900|USFWorkChain|validate_slipping_system]: Now we are working on 100 gliding plane.\n",
      "04/28/2025 03:17:04 PM <885922> aiida.orm.nodes.process.workflow.workchain.WorkChainNode: [REPORT] [71900|USFWorkChain|validate_slipping_system]: Faulting is possible for 100 gliding plane.The stacking order is AB. Slipping direction: 1/2[110]. \n",
      "04/28/2025 03:17:04 PM <885922> aiida.orm.nodes.process.workflow.workchain.WorkChainNode: [REPORT] [71900|USFWorkChain|run_scf]: launching PwCalculation<71901> for V unit cell geometry.\n",
      "04/28/2025 03:17:35 PM <885922> aiida.transport.SshTransport: [ERROR] Error connecting to proxy 'gwceci.cism.ucl.ac.be' through SSH: [SshTransport] Authentication failed., connect_args were: {'username': 'yimzhang', 'port': 22, 'look_for_keys': True, 'key_filename': '/home/ucl/modl/yimzhang/.ssh/id_rsa.ceci', 'timeout': 60, 'allow_agent': True, 'compress': True, 'gss_auth': False, 'gss_kex': False, 'gss_deleg_creds': False, 'gss_host': 'frontal.lucia.cenaero.be'}\n",
      "04/28/2025 03:17:35 PM <885922> aiida.engine.transports: [ERROR] exception occurred while trying to open transport:\n",
      " Authentication failed.\n",
      "04/28/2025 03:17:35 PM <885922> aiida.engine.transports: [ERROR] Exception whilst using transport:\n",
      "Traceback (most recent call last):\n",
      "  File \"/home/ucl/modl/yimzhang/miniforge3/envs/aiida-240/lib/python3.11/site-packages/aiida/engine/transports.py\", line 106, in request_transport\n",
      "    yield transport_request.future\n",
      "  File \"/home/ucl/modl/yimzhang/miniforge3/envs/aiida-240/lib/python3.11/site-packages/aiida/engine/processes/calcjobs/tasks.py\", line 86, in do_upload\n",
      "    transport = await cancellable.with_interrupt(request)\n",
      "                ^^^^^^^^^^^^^^^^^^^^^^^^^^^^^^^^^^^^^^^^^\n",
      "  File \"/home/ucl/modl/yimzhang/miniforge3/envs/aiida-240/lib/python3.11/site-packages/aiida/engine/utils.py\", line 115, in with_interrupt\n",
      "    result = await next(wait_iter)\n",
      "             ^^^^^^^^^^^^^^^^^^^^^\n",
      "  File \"/home/ucl/modl/yimzhang/miniforge3/envs/aiida-240/lib/python3.11/asyncio/tasks.py\", line 605, in _wait_for_one\n",
      "    return f.result()  # May raise f.exception().\n",
      "           ^^^^^^^^^^\n",
      "  File \"/home/ucl/modl/yimzhang/miniforge3/envs/aiida-240/lib/python3.11/asyncio/futures.py\", line 203, in result\n",
      "    raise self._exception.with_traceback(self._exception_tb)\n",
      "  File \"/home/ucl/modl/yimzhang/miniforge3/envs/aiida-240/lib/python3.11/site-packages/aiida/engine/transports.py\", line 87, in do_open\n",
      "    transport.open()\n",
      "  File \"/home/ucl/modl/yimzhang/miniforge3/envs/aiida-240/lib/python3.11/site-packages/aiida/transports/plugins/ssh.py\", line 480, in open\n",
      "    proxy_client.connect(proxy['host'], **proxy_connargs)\n",
      "  File \"/home/ucl/modl/yimzhang/miniforge3/envs/aiida-240/lib/python3.11/site-packages/paramiko/client.py\", line 450, in connect\n",
      "    self._auth(\n",
      "  File \"/home/ucl/modl/yimzhang/miniforge3/envs/aiida-240/lib/python3.11/site-packages/paramiko/client.py\", line 781, in _auth\n",
      "    raise saved_exception\n",
      "  File \"/home/ucl/modl/yimzhang/miniforge3/envs/aiida-240/lib/python3.11/site-packages/paramiko/client.py\", line 757, in _auth\n",
      "    self._transport.auth_publickey(username, key)\n",
      "  File \"/home/ucl/modl/yimzhang/miniforge3/envs/aiida-240/lib/python3.11/site-packages/paramiko/transport.py\", line 1635, in auth_publickey\n",
      "    return self.auth_handler.wait_for_response(my_event)\n",
      "           ^^^^^^^^^^^^^^^^^^^^^^^^^^^^^^^^^^^^^^^^^^^^^\n",
      "  File \"/home/ucl/modl/yimzhang/miniforge3/envs/aiida-240/lib/python3.11/site-packages/paramiko/auth_handler.py\", line 259, in wait_for_response\n",
      "    raise e\n",
      "paramiko.ssh_exception.AuthenticationException: Authentication failed.\n",
      "\n",
      "04/28/2025 03:17:35 PM <885922> aiida.orm.nodes.process.calculation.calcjob.CalcJobNode: [ERROR] iteration 1 of do_upload excepted, retrying after 20 seconds\n",
      "Traceback (most recent call last):\n",
      "  File \"/home/ucl/modl/yimzhang/miniforge3/envs/aiida-240/lib/python3.11/site-packages/aiida/engine/utils.py\", line 205, in exponential_backoff_retry\n",
      "    result = await coro()\n",
      "             ^^^^^^^^^^^^\n",
      "  File \"/home/ucl/modl/yimzhang/miniforge3/envs/aiida-240/lib/python3.11/site-packages/aiida/engine/processes/calcjobs/tasks.py\", line 86, in do_upload\n",
      "    transport = await cancellable.with_interrupt(request)\n",
      "                ^^^^^^^^^^^^^^^^^^^^^^^^^^^^^^^^^^^^^^^^^\n",
      "  File \"/home/ucl/modl/yimzhang/miniforge3/envs/aiida-240/lib/python3.11/site-packages/aiida/engine/utils.py\", line 115, in with_interrupt\n",
      "    result = await next(wait_iter)\n",
      "             ^^^^^^^^^^^^^^^^^^^^^\n",
      "  File \"/home/ucl/modl/yimzhang/miniforge3/envs/aiida-240/lib/python3.11/asyncio/tasks.py\", line 605, in _wait_for_one\n",
      "    return f.result()  # May raise f.exception().\n",
      "           ^^^^^^^^^^\n",
      "  File \"/home/ucl/modl/yimzhang/miniforge3/envs/aiida-240/lib/python3.11/asyncio/futures.py\", line 203, in result\n",
      "    raise self._exception.with_traceback(self._exception_tb)\n",
      "  File \"/home/ucl/modl/yimzhang/miniforge3/envs/aiida-240/lib/python3.11/site-packages/aiida/engine/transports.py\", line 87, in do_open\n",
      "    transport.open()\n",
      "  File \"/home/ucl/modl/yimzhang/miniforge3/envs/aiida-240/lib/python3.11/site-packages/aiida/transports/plugins/ssh.py\", line 480, in open\n",
      "    proxy_client.connect(proxy['host'], **proxy_connargs)\n",
      "  File \"/home/ucl/modl/yimzhang/miniforge3/envs/aiida-240/lib/python3.11/site-packages/paramiko/client.py\", line 450, in connect\n",
      "    self._auth(\n",
      "  File \"/home/ucl/modl/yimzhang/miniforge3/envs/aiida-240/lib/python3.11/site-packages/paramiko/client.py\", line 781, in _auth\n",
      "    raise saved_exception\n",
      "  File \"/home/ucl/modl/yimzhang/miniforge3/envs/aiida-240/lib/python3.11/site-packages/paramiko/client.py\", line 757, in _auth\n",
      "    self._transport.auth_publickey(username, key)\n",
      "  File \"/home/ucl/modl/yimzhang/miniforge3/envs/aiida-240/lib/python3.11/site-packages/paramiko/transport.py\", line 1635, in auth_publickey\n",
      "    return self.auth_handler.wait_for_response(my_event)\n",
      "           ^^^^^^^^^^^^^^^^^^^^^^^^^^^^^^^^^^^^^^^^^^^^^\n",
      "  File \"/home/ucl/modl/yimzhang/miniforge3/envs/aiida-240/lib/python3.11/site-packages/paramiko/auth_handler.py\", line 259, in wait_for_response\n",
      "    raise e\n",
      "paramiko.ssh_exception.AuthenticationException: Authentication failed.\n",
      "04/28/2025 03:18:25 PM <885922> aiida.transport.SshTransport: [ERROR] Error connecting to proxy 'gwceci.cism.ucl.ac.be' through SSH: [SshTransport] Authentication failed., connect_args were: {'username': 'yimzhang', 'port': 22, 'look_for_keys': True, 'key_filename': '/home/ucl/modl/yimzhang/.ssh/id_rsa.ceci', 'timeout': 60, 'allow_agent': True, 'compress': True, 'gss_auth': False, 'gss_kex': False, 'gss_deleg_creds': False, 'gss_host': 'frontal.lucia.cenaero.be'}\n",
      "04/28/2025 03:18:25 PM <885922> aiida.engine.transports: [ERROR] exception occurred while trying to open transport:\n",
      " Authentication failed.\n",
      "04/28/2025 03:18:25 PM <885922> aiida.engine.transports: [ERROR] Exception whilst using transport:\n",
      "Traceback (most recent call last):\n",
      "  File \"/home/ucl/modl/yimzhang/miniforge3/envs/aiida-240/lib/python3.11/site-packages/aiida/engine/transports.py\", line 106, in request_transport\n",
      "    yield transport_request.future\n",
      "  File \"/home/ucl/modl/yimzhang/miniforge3/envs/aiida-240/lib/python3.11/site-packages/aiida/engine/processes/calcjobs/tasks.py\", line 86, in do_upload\n",
      "    transport = await cancellable.with_interrupt(request)\n",
      "                ^^^^^^^^^^^^^^^^^^^^^^^^^^^^^^^^^^^^^^^^^\n",
      "  File \"/home/ucl/modl/yimzhang/miniforge3/envs/aiida-240/lib/python3.11/site-packages/aiida/engine/utils.py\", line 115, in with_interrupt\n",
      "    result = await next(wait_iter)\n",
      "             ^^^^^^^^^^^^^^^^^^^^^\n",
      "  File \"/home/ucl/modl/yimzhang/miniforge3/envs/aiida-240/lib/python3.11/asyncio/tasks.py\", line 605, in _wait_for_one\n",
      "    return f.result()  # May raise f.exception().\n",
      "           ^^^^^^^^^^\n",
      "  File \"/home/ucl/modl/yimzhang/miniforge3/envs/aiida-240/lib/python3.11/asyncio/futures.py\", line 203, in result\n",
      "    raise self._exception.with_traceback(self._exception_tb)\n",
      "  File \"/home/ucl/modl/yimzhang/miniforge3/envs/aiida-240/lib/python3.11/site-packages/aiida/engine/transports.py\", line 87, in do_open\n",
      "    transport.open()\n",
      "  File \"/home/ucl/modl/yimzhang/miniforge3/envs/aiida-240/lib/python3.11/site-packages/aiida/transports/plugins/ssh.py\", line 480, in open\n",
      "    proxy_client.connect(proxy['host'], **proxy_connargs)\n",
      "  File \"/home/ucl/modl/yimzhang/miniforge3/envs/aiida-240/lib/python3.11/site-packages/paramiko/client.py\", line 450, in connect\n",
      "    self._auth(\n",
      "  File \"/home/ucl/modl/yimzhang/miniforge3/envs/aiida-240/lib/python3.11/site-packages/paramiko/client.py\", line 781, in _auth\n",
      "    raise saved_exception\n",
      "  File \"/home/ucl/modl/yimzhang/miniforge3/envs/aiida-240/lib/python3.11/site-packages/paramiko/client.py\", line 757, in _auth\n",
      "    self._transport.auth_publickey(username, key)\n",
      "  File \"/home/ucl/modl/yimzhang/miniforge3/envs/aiida-240/lib/python3.11/site-packages/paramiko/transport.py\", line 1635, in auth_publickey\n",
      "    return self.auth_handler.wait_for_response(my_event)\n",
      "           ^^^^^^^^^^^^^^^^^^^^^^^^^^^^^^^^^^^^^^^^^^^^^\n",
      "  File \"/home/ucl/modl/yimzhang/miniforge3/envs/aiida-240/lib/python3.11/site-packages/paramiko/auth_handler.py\", line 259, in wait_for_response\n",
      "    raise e\n",
      "paramiko.ssh_exception.AuthenticationException: Authentication failed.\n",
      "\n",
      "04/28/2025 03:18:25 PM <885922> aiida.orm.nodes.process.calculation.calcjob.CalcJobNode: [ERROR] iteration 2 of do_upload excepted, retrying after 40 seconds\n",
      "Traceback (most recent call last):\n",
      "  File \"/home/ucl/modl/yimzhang/miniforge3/envs/aiida-240/lib/python3.11/site-packages/aiida/engine/utils.py\", line 205, in exponential_backoff_retry\n",
      "    result = await coro()\n",
      "             ^^^^^^^^^^^^\n",
      "  File \"/home/ucl/modl/yimzhang/miniforge3/envs/aiida-240/lib/python3.11/site-packages/aiida/engine/processes/calcjobs/tasks.py\", line 86, in do_upload\n",
      "    transport = await cancellable.with_interrupt(request)\n",
      "                ^^^^^^^^^^^^^^^^^^^^^^^^^^^^^^^^^^^^^^^^^\n",
      "  File \"/home/ucl/modl/yimzhang/miniforge3/envs/aiida-240/lib/python3.11/site-packages/aiida/engine/utils.py\", line 115, in with_interrupt\n",
      "    result = await next(wait_iter)\n",
      "             ^^^^^^^^^^^^^^^^^^^^^\n",
      "  File \"/home/ucl/modl/yimzhang/miniforge3/envs/aiida-240/lib/python3.11/asyncio/tasks.py\", line 605, in _wait_for_one\n",
      "    return f.result()  # May raise f.exception().\n",
      "           ^^^^^^^^^^\n",
      "  File \"/home/ucl/modl/yimzhang/miniforge3/envs/aiida-240/lib/python3.11/asyncio/futures.py\", line 203, in result\n",
      "    raise self._exception.with_traceback(self._exception_tb)\n",
      "  File \"/home/ucl/modl/yimzhang/miniforge3/envs/aiida-240/lib/python3.11/site-packages/aiida/engine/transports.py\", line 87, in do_open\n",
      "    transport.open()\n",
      "  File \"/home/ucl/modl/yimzhang/miniforge3/envs/aiida-240/lib/python3.11/site-packages/aiida/transports/plugins/ssh.py\", line 480, in open\n",
      "    proxy_client.connect(proxy['host'], **proxy_connargs)\n",
      "  File \"/home/ucl/modl/yimzhang/miniforge3/envs/aiida-240/lib/python3.11/site-packages/paramiko/client.py\", line 450, in connect\n",
      "    self._auth(\n",
      "  File \"/home/ucl/modl/yimzhang/miniforge3/envs/aiida-240/lib/python3.11/site-packages/paramiko/client.py\", line 781, in _auth\n",
      "    raise saved_exception\n",
      "  File \"/home/ucl/modl/yimzhang/miniforge3/envs/aiida-240/lib/python3.11/site-packages/paramiko/client.py\", line 757, in _auth\n",
      "    self._transport.auth_publickey(username, key)\n",
      "  File \"/home/ucl/modl/yimzhang/miniforge3/envs/aiida-240/lib/python3.11/site-packages/paramiko/transport.py\", line 1635, in auth_publickey\n",
      "    return self.auth_handler.wait_for_response(my_event)\n",
      "           ^^^^^^^^^^^^^^^^^^^^^^^^^^^^^^^^^^^^^^^^^^^^^\n",
      "  File \"/home/ucl/modl/yimzhang/miniforge3/envs/aiida-240/lib/python3.11/site-packages/paramiko/auth_handler.py\", line 259, in wait_for_response\n",
      "    raise e\n",
      "paramiko.ssh_exception.AuthenticationException: Authentication failed.\n",
      "04/28/2025 03:18:50 PM <885922> aiida.engine.runners: [CRITICAL] runner received interrupt, killing process 71900\n",
      "04/28/2025 03:18:51 PM <885922> aiida.orm.nodes.process.workflow.workchain.WorkChainNode: [REPORT] [71900|USFWorkChain|on_terminated]: remote folders will not be cleaned\n"
     ]
    },
    {
     "ename": "KilledError",
     "evalue": "Process was killed because the runner received an interrupt",
     "output_type": "error",
     "traceback": [
      "\u001b[31m---------------------------------------------------------------------------\u001b[39m",
      "\u001b[31mKilledError\u001b[39m                               Traceback (most recent call last)",
      "\u001b[36mCell\u001b[39m\u001b[36m \u001b[39m\u001b[32mIn[5]\u001b[39m\u001b[32m, line 8\u001b[39m\n\u001b[32m      5\u001b[39m logging.getLogger(\u001b[33m'\u001b[39m\u001b[33maiida.transport.SshTransport\u001b[39m\u001b[33m'\u001b[39m) .setLevel(logging.ERROR)\n\u001b[32m      6\u001b[39m logging.getLogger(\u001b[33m'\u001b[39m\u001b[33maiida.scheduler.slurm\u001b[39m\u001b[33m'\u001b[39m).setLevel(logging.ERROR)\n\u001b[32m----> \u001b[39m\u001b[32m8\u001b[39m test_node = \u001b[43mrun\u001b[49m\u001b[43m.\u001b[49m\u001b[43mget_node\u001b[49m\u001b[43m(\u001b[49m\u001b[43mUSFWorkChain\u001b[49m\u001b[43m,\u001b[49m\u001b[43m \u001b[49m\u001b[43m*\u001b[49m\u001b[43m*\u001b[49m\u001b[43minputs\u001b[49m\u001b[43m)\u001b[49m\n\u001b[32m      9\u001b[39m test_USF_group.add_nodes(test_node.node)\n",
      "\u001b[36mFile \u001b[39m\u001b[32m~/miniforge3/envs/aiida-240/lib/python3.11/site-packages/aiida/engine/launch.py:65\u001b[39m, in \u001b[36mrun_get_node\u001b[39m\u001b[34m(process, inputs, **kwargs)\u001b[39m\n\u001b[32m     62\u001b[39m \u001b[38;5;28;01melse\u001b[39;00m:\n\u001b[32m     63\u001b[39m     runner = manager.get_manager().get_runner()\n\u001b[32m---> \u001b[39m\u001b[32m65\u001b[39m \u001b[38;5;28;01mreturn\u001b[39;00m \u001b[43mrunner\u001b[49m\u001b[43m.\u001b[49m\u001b[43mrun_get_node\u001b[49m\u001b[43m(\u001b[49m\u001b[43mprocess\u001b[49m\u001b[43m,\u001b[49m\u001b[43m \u001b[49m\u001b[43minputs\u001b[49m\u001b[43m,\u001b[49m\u001b[43m \u001b[49m\u001b[43m*\u001b[49m\u001b[43m*\u001b[49m\u001b[43mkwargs\u001b[49m\u001b[43m)\u001b[49m\n",
      "\u001b[36mFile \u001b[39m\u001b[32m~/miniforge3/envs/aiida-240/lib/python3.11/site-packages/aiida/engine/runners.py:291\u001b[39m, in \u001b[36mRunner.run_get_node\u001b[39m\u001b[34m(self, process, inputs, **kwargs)\u001b[39m\n\u001b[32m    280\u001b[39m \u001b[38;5;28;01mdef\u001b[39;00m\u001b[38;5;250m \u001b[39m\u001b[34mrun_get_node\u001b[39m(\n\u001b[32m    281\u001b[39m     \u001b[38;5;28mself\u001b[39m, process: TYPE_RUN_PROCESS, inputs: \u001b[38;5;28mdict\u001b[39m[\u001b[38;5;28mstr\u001b[39m, Any] | \u001b[38;5;28;01mNone\u001b[39;00m = \u001b[38;5;28;01mNone\u001b[39;00m, **kwargs: Any\n\u001b[32m    282\u001b[39m ) -> ResultAndNode:\n\u001b[32m    283\u001b[39m \u001b[38;5;250m    \u001b[39m\u001b[33;03m\"\"\"Run the process with the supplied inputs in this runner that will block until the process is completed.\u001b[39;00m\n\u001b[32m    284\u001b[39m \n\u001b[32m    285\u001b[39m \u001b[33;03m    The return value will be the results of the completed process\u001b[39;00m\n\u001b[32m   (...)\u001b[39m\u001b[32m    289\u001b[39m \u001b[33;03m    :return: tuple of the outputs of the process and the calculation node\u001b[39;00m\n\u001b[32m    290\u001b[39m \u001b[33;03m    \"\"\"\u001b[39;00m\n\u001b[32m--> \u001b[39m\u001b[32m291\u001b[39m     result, node = \u001b[38;5;28;43mself\u001b[39;49m\u001b[43m.\u001b[49m\u001b[43m_run\u001b[49m\u001b[43m(\u001b[49m\u001b[43mprocess\u001b[49m\u001b[43m,\u001b[49m\u001b[43m \u001b[49m\u001b[43minputs\u001b[49m\u001b[43m,\u001b[49m\u001b[43m \u001b[49m\u001b[43m*\u001b[49m\u001b[43m*\u001b[49m\u001b[43mkwargs\u001b[49m\u001b[43m)\u001b[49m\n\u001b[32m    292\u001b[39m     \u001b[38;5;28;01mreturn\u001b[39;00m ResultAndNode(result, node)\n",
      "\u001b[36mFile \u001b[39m\u001b[32m~/miniforge3/envs/aiida-240/lib/python3.11/site-packages/aiida/engine/runners.py:261\u001b[39m, in \u001b[36mRunner._run\u001b[39m\u001b[34m(self, process, inputs, **kwargs)\u001b[39m\n\u001b[32m    259\u001b[39m     signal.signal(signal.SIGINT, kill_process)\n\u001b[32m    260\u001b[39m     signal.signal(signal.SIGTERM, kill_process)\n\u001b[32m--> \u001b[39m\u001b[32m261\u001b[39m     \u001b[43mprocess_inited\u001b[49m\u001b[43m.\u001b[49m\u001b[43mexecute\u001b[49m\u001b[43m(\u001b[49m\u001b[43m)\u001b[49m\n\u001b[32m    262\u001b[39m \u001b[38;5;28;01mfinally\u001b[39;00m:\n\u001b[32m    263\u001b[39m     signal.signal(signal.SIGINT, original_handler_int)\n",
      "\u001b[36mFile \u001b[39m\u001b[32m~/miniforge3/envs/aiida-240/lib/python3.11/site-packages/plumpy/processes.py:86\u001b[39m, in \u001b[36mensure_not_closed.<locals>.func_wrapper\u001b[39m\u001b[34m(self, *args, **kwargs)\u001b[39m\n\u001b[32m     84\u001b[39m \u001b[38;5;28;01mif\u001b[39;00m \u001b[38;5;28mself\u001b[39m._closed:\n\u001b[32m     85\u001b[39m     \u001b[38;5;28;01mraise\u001b[39;00m exceptions.ClosedError(\u001b[33m'\u001b[39m\u001b[33mProcess is closed\u001b[39m\u001b[33m'\u001b[39m)\n\u001b[32m---> \u001b[39m\u001b[32m86\u001b[39m \u001b[38;5;28;01mreturn\u001b[39;00m \u001b[43mfunc\u001b[49m\u001b[43m(\u001b[49m\u001b[38;5;28;43mself\u001b[39;49m\u001b[43m,\u001b[49m\u001b[43m \u001b[49m\u001b[43m*\u001b[49m\u001b[43margs\u001b[49m\u001b[43m,\u001b[49m\u001b[43m \u001b[49m\u001b[43m*\u001b[49m\u001b[43m*\u001b[49m\u001b[43mkwargs\u001b[49m\u001b[43m)\u001b[49m\n",
      "\u001b[36mFile \u001b[39m\u001b[32m~/miniforge3/envs/aiida-240/lib/python3.11/site-packages/plumpy/processes.py:1197\u001b[39m, in \u001b[36mProcess.execute\u001b[39m\u001b[34m(self)\u001b[39m\n\u001b[32m   1194\u001b[39m \u001b[38;5;28;01mif\u001b[39;00m \u001b[38;5;129;01mnot\u001b[39;00m \u001b[38;5;28mself\u001b[39m.has_terminated():\n\u001b[32m   1195\u001b[39m     \u001b[38;5;28mself\u001b[39m.loop.run_until_complete(\u001b[38;5;28mself\u001b[39m.step_until_terminated())\n\u001b[32m-> \u001b[39m\u001b[32m1197\u001b[39m \u001b[38;5;28;01mreturn\u001b[39;00m \u001b[38;5;28;43mself\u001b[39;49m\u001b[43m.\u001b[49m\u001b[43mfuture\u001b[49m\u001b[43m(\u001b[49m\u001b[43m)\u001b[49m\u001b[43m.\u001b[49m\u001b[43mresult\u001b[49m\u001b[43m(\u001b[49m\u001b[43m)\u001b[49m\n",
      "\u001b[31mKilledError\u001b[39m: Process was killed because the runner received an interrupt"
     ]
    },
    {
     "name": "stderr",
     "output_type": "stream",
     "text": [
      "04/28/2025 03:19:05 PM <885922> aiida.engine.transports: [ERROR] Exception whilst using transport:\n",
      "Traceback (most recent call last):\n",
      "  File \"/home/ucl/modl/yimzhang/miniforge3/envs/aiida-240/lib/python3.11/site-packages/aiida/engine/transports.py\", line 106, in request_transport\n",
      "    yield transport_request.future\n",
      "  File \"/home/ucl/modl/yimzhang/miniforge3/envs/aiida-240/lib/python3.11/site-packages/aiida/engine/processes/calcjobs/tasks.py\", line 86, in do_upload\n",
      "    transport = await cancellable.with_interrupt(request)\n",
      "                ^^^^^^^^^^^^^^^^^^^^^^^^^^^^^^^^^^^^^^^^^\n",
      "  File \"/home/ucl/modl/yimzhang/miniforge3/envs/aiida-240/lib/python3.11/site-packages/aiida/engine/utils.py\", line 115, in with_interrupt\n",
      "    result = await next(wait_iter)\n",
      "             ^^^^^^^^^^^^^^^^^^^^^\n",
      "  File \"/home/ucl/modl/yimzhang/miniforge3/envs/aiida-240/lib/python3.11/asyncio/tasks.py\", line 605, in _wait_for_one\n",
      "    return f.result()  # May raise f.exception().\n",
      "           ^^^^^^^^^^\n",
      "plumpy.process_states.KillInterruption: Killed by parent<71900>\n",
      "\n",
      "04/28/2025 03:19:21 PM <885922> aiida.engine.transports: [ERROR] Exception whilst using transport:\n",
      "Traceback (most recent call last):\n",
      "  File \"/home/ucl/modl/yimzhang/miniforge3/envs/aiida-240/lib/python3.11/site-packages/aiida/engine/transports.py\", line 106, in request_transport\n",
      "    yield transport_request.future\n",
      "  File \"/home/ucl/modl/yimzhang/miniforge3/envs/aiida-240/lib/python3.11/site-packages/aiida/engine/processes/calcjobs/tasks.py\", line 426, in do_kill\n",
      "    transport = await cancellable.with_interrupt(request)\n",
      "                ^^^^^^^^^^^^^^^^^^^^^^^^^^^^^^^^^^^^^^^^^\n",
      "  File \"/home/ucl/modl/yimzhang/miniforge3/envs/aiida-240/lib/python3.11/site-packages/aiida/engine/utils.py\", line 115, in with_interrupt\n",
      "    result = await next(wait_iter)\n",
      "             ^^^^^^^^^^^^^^^^^^^^^\n",
      "  File \"/home/ucl/modl/yimzhang/miniforge3/envs/aiida-240/lib/python3.11/asyncio/tasks.py\", line 605, in _wait_for_one\n",
      "    return f.result()  # May raise f.exception().\n",
      "           ^^^^^^^^^^\n",
      "  File \"/home/ucl/modl/yimzhang/miniforge3/envs/aiida-240/lib/python3.11/asyncio/futures.py\", line 203, in result\n",
      "    raise self._exception.with_traceback(self._exception_tb)\n",
      "  File \"/home/ucl/modl/yimzhang/miniforge3/envs/aiida-240/lib/python3.11/site-packages/aiida/engine/transports.py\", line 87, in do_open\n",
      "    transport.open()\n",
      "  File \"/home/ucl/modl/yimzhang/miniforge3/envs/aiida-240/lib/python3.11/site-packages/aiida/transports/plugins/ssh.py\", line 480, in open\n",
      "    proxy_client.connect(proxy['host'], **proxy_connargs)\n",
      "  File \"/home/ucl/modl/yimzhang/miniforge3/envs/aiida-240/lib/python3.11/site-packages/paramiko/client.py\", line 450, in connect\n",
      "    self._auth(\n",
      "  File \"/home/ucl/modl/yimzhang/miniforge3/envs/aiida-240/lib/python3.11/site-packages/paramiko/client.py\", line 781, in _auth\n",
      "    raise saved_exception\n",
      "  File \"/home/ucl/modl/yimzhang/miniforge3/envs/aiida-240/lib/python3.11/site-packages/paramiko/client.py\", line 757, in _auth\n",
      "    self._transport.auth_publickey(username, key)\n",
      "  File \"/home/ucl/modl/yimzhang/miniforge3/envs/aiida-240/lib/python3.11/site-packages/paramiko/transport.py\", line 1635, in auth_publickey\n",
      "    return self.auth_handler.wait_for_response(my_event)\n",
      "           ^^^^^^^^^^^^^^^^^^^^^^^^^^^^^^^^^^^^^^^^^^^^^\n",
      "  File \"/home/ucl/modl/yimzhang/miniforge3/envs/aiida-240/lib/python3.11/site-packages/paramiko/auth_handler.py\", line 259, in wait_for_response\n",
      "    raise e\n",
      "paramiko.ssh_exception.AuthenticationException: Authentication failed.\n",
      "\n",
      "04/28/2025 03:19:21 PM <885922> aiida.orm.nodes.process.calculation.calcjob.CalcJobNode: [ERROR] iteration 1 of do_kill excepted, retrying after 20 seconds\n",
      "Traceback (most recent call last):\n",
      "  File \"/home/ucl/modl/yimzhang/miniforge3/envs/aiida-240/lib/python3.11/site-packages/aiida/engine/utils.py\", line 205, in exponential_backoff_retry\n",
      "    result = await coro()\n",
      "             ^^^^^^^^^^^^\n",
      "  File \"/home/ucl/modl/yimzhang/miniforge3/envs/aiida-240/lib/python3.11/site-packages/aiida/engine/processes/calcjobs/tasks.py\", line 426, in do_kill\n",
      "    transport = await cancellable.with_interrupt(request)\n",
      "                ^^^^^^^^^^^^^^^^^^^^^^^^^^^^^^^^^^^^^^^^^\n",
      "  File \"/home/ucl/modl/yimzhang/miniforge3/envs/aiida-240/lib/python3.11/site-packages/aiida/engine/utils.py\", line 115, in with_interrupt\n",
      "    result = await next(wait_iter)\n",
      "             ^^^^^^^^^^^^^^^^^^^^^\n",
      "  File \"/home/ucl/modl/yimzhang/miniforge3/envs/aiida-240/lib/python3.11/asyncio/tasks.py\", line 605, in _wait_for_one\n",
      "    return f.result()  # May raise f.exception().\n",
      "           ^^^^^^^^^^\n",
      "  File \"/home/ucl/modl/yimzhang/miniforge3/envs/aiida-240/lib/python3.11/asyncio/futures.py\", line 203, in result\n",
      "    raise self._exception.with_traceback(self._exception_tb)\n",
      "  File \"/home/ucl/modl/yimzhang/miniforge3/envs/aiida-240/lib/python3.11/site-packages/aiida/engine/transports.py\", line 87, in do_open\n",
      "    transport.open()\n",
      "  File \"/home/ucl/modl/yimzhang/miniforge3/envs/aiida-240/lib/python3.11/site-packages/aiida/transports/plugins/ssh.py\", line 480, in open\n",
      "    proxy_client.connect(proxy['host'], **proxy_connargs)\n",
      "  File \"/home/ucl/modl/yimzhang/miniforge3/envs/aiida-240/lib/python3.11/site-packages/paramiko/client.py\", line 450, in connect\n",
      "    self._auth(\n",
      "  File \"/home/ucl/modl/yimzhang/miniforge3/envs/aiida-240/lib/python3.11/site-packages/paramiko/client.py\", line 781, in _auth\n",
      "    raise saved_exception\n",
      "  File \"/home/ucl/modl/yimzhang/miniforge3/envs/aiida-240/lib/python3.11/site-packages/paramiko/client.py\", line 757, in _auth\n",
      "    self._transport.auth_publickey(username, key)\n",
      "  File \"/home/ucl/modl/yimzhang/miniforge3/envs/aiida-240/lib/python3.11/site-packages/paramiko/transport.py\", line 1635, in auth_publickey\n",
      "    return self.auth_handler.wait_for_response(my_event)\n",
      "           ^^^^^^^^^^^^^^^^^^^^^^^^^^^^^^^^^^^^^^^^^^^^^\n",
      "  File \"/home/ucl/modl/yimzhang/miniforge3/envs/aiida-240/lib/python3.11/site-packages/paramiko/auth_handler.py\", line 259, in wait_for_response\n",
      "    raise e\n",
      "paramiko.ssh_exception.AuthenticationException: Authentication failed.\n",
      "04/28/2025 03:20:11 PM <885922> aiida.engine.transports: [ERROR] Exception whilst using transport:\n",
      "Traceback (most recent call last):\n",
      "  File \"/home/ucl/modl/yimzhang/miniforge3/envs/aiida-240/lib/python3.11/site-packages/aiida/engine/transports.py\", line 106, in request_transport\n",
      "    yield transport_request.future\n",
      "  File \"/home/ucl/modl/yimzhang/miniforge3/envs/aiida-240/lib/python3.11/site-packages/aiida/engine/processes/calcjobs/tasks.py\", line 426, in do_kill\n",
      "    transport = await cancellable.with_interrupt(request)\n",
      "                ^^^^^^^^^^^^^^^^^^^^^^^^^^^^^^^^^^^^^^^^^\n",
      "  File \"/home/ucl/modl/yimzhang/miniforge3/envs/aiida-240/lib/python3.11/site-packages/aiida/engine/utils.py\", line 115, in with_interrupt\n",
      "    result = await next(wait_iter)\n",
      "             ^^^^^^^^^^^^^^^^^^^^^\n",
      "  File \"/home/ucl/modl/yimzhang/miniforge3/envs/aiida-240/lib/python3.11/asyncio/tasks.py\", line 605, in _wait_for_one\n",
      "    return f.result()  # May raise f.exception().\n",
      "           ^^^^^^^^^^\n",
      "  File \"/home/ucl/modl/yimzhang/miniforge3/envs/aiida-240/lib/python3.11/asyncio/futures.py\", line 203, in result\n",
      "    raise self._exception.with_traceback(self._exception_tb)\n",
      "  File \"/home/ucl/modl/yimzhang/miniforge3/envs/aiida-240/lib/python3.11/site-packages/aiida/engine/transports.py\", line 87, in do_open\n",
      "    transport.open()\n",
      "  File \"/home/ucl/modl/yimzhang/miniforge3/envs/aiida-240/lib/python3.11/site-packages/aiida/transports/plugins/ssh.py\", line 480, in open\n",
      "    proxy_client.connect(proxy['host'], **proxy_connargs)\n",
      "  File \"/home/ucl/modl/yimzhang/miniforge3/envs/aiida-240/lib/python3.11/site-packages/paramiko/client.py\", line 450, in connect\n",
      "    self._auth(\n",
      "  File \"/home/ucl/modl/yimzhang/miniforge3/envs/aiida-240/lib/python3.11/site-packages/paramiko/client.py\", line 781, in _auth\n",
      "    raise saved_exception\n",
      "  File \"/home/ucl/modl/yimzhang/miniforge3/envs/aiida-240/lib/python3.11/site-packages/paramiko/client.py\", line 757, in _auth\n",
      "    self._transport.auth_publickey(username, key)\n",
      "  File \"/home/ucl/modl/yimzhang/miniforge3/envs/aiida-240/lib/python3.11/site-packages/paramiko/transport.py\", line 1635, in auth_publickey\n",
      "    return self.auth_handler.wait_for_response(my_event)\n",
      "           ^^^^^^^^^^^^^^^^^^^^^^^^^^^^^^^^^^^^^^^^^^^^^\n",
      "  File \"/home/ucl/modl/yimzhang/miniforge3/envs/aiida-240/lib/python3.11/site-packages/paramiko/auth_handler.py\", line 259, in wait_for_response\n",
      "    raise e\n",
      "paramiko.ssh_exception.AuthenticationException: Authentication failed.\n",
      "\n",
      "04/28/2025 03:20:11 PM <885922> aiida.orm.nodes.process.calculation.calcjob.CalcJobNode: [ERROR] iteration 2 of do_kill excepted, retrying after 40 seconds\n",
      "Traceback (most recent call last):\n",
      "  File \"/home/ucl/modl/yimzhang/miniforge3/envs/aiida-240/lib/python3.11/site-packages/aiida/engine/utils.py\", line 205, in exponential_backoff_retry\n",
      "    result = await coro()\n",
      "             ^^^^^^^^^^^^\n",
      "  File \"/home/ucl/modl/yimzhang/miniforge3/envs/aiida-240/lib/python3.11/site-packages/aiida/engine/processes/calcjobs/tasks.py\", line 426, in do_kill\n",
      "    transport = await cancellable.with_interrupt(request)\n",
      "                ^^^^^^^^^^^^^^^^^^^^^^^^^^^^^^^^^^^^^^^^^\n",
      "  File \"/home/ucl/modl/yimzhang/miniforge3/envs/aiida-240/lib/python3.11/site-packages/aiida/engine/utils.py\", line 115, in with_interrupt\n",
      "    result = await next(wait_iter)\n",
      "             ^^^^^^^^^^^^^^^^^^^^^\n",
      "  File \"/home/ucl/modl/yimzhang/miniforge3/envs/aiida-240/lib/python3.11/asyncio/tasks.py\", line 605, in _wait_for_one\n",
      "    return f.result()  # May raise f.exception().\n",
      "           ^^^^^^^^^^\n",
      "  File \"/home/ucl/modl/yimzhang/miniforge3/envs/aiida-240/lib/python3.11/asyncio/futures.py\", line 203, in result\n",
      "    raise self._exception.with_traceback(self._exception_tb)\n",
      "  File \"/home/ucl/modl/yimzhang/miniforge3/envs/aiida-240/lib/python3.11/site-packages/aiida/engine/transports.py\", line 87, in do_open\n",
      "    transport.open()\n",
      "  File \"/home/ucl/modl/yimzhang/miniforge3/envs/aiida-240/lib/python3.11/site-packages/aiida/transports/plugins/ssh.py\", line 480, in open\n",
      "    proxy_client.connect(proxy['host'], **proxy_connargs)\n",
      "  File \"/home/ucl/modl/yimzhang/miniforge3/envs/aiida-240/lib/python3.11/site-packages/paramiko/client.py\", line 450, in connect\n",
      "    self._auth(\n",
      "  File \"/home/ucl/modl/yimzhang/miniforge3/envs/aiida-240/lib/python3.11/site-packages/paramiko/client.py\", line 781, in _auth\n",
      "    raise saved_exception\n",
      "  File \"/home/ucl/modl/yimzhang/miniforge3/envs/aiida-240/lib/python3.11/site-packages/paramiko/client.py\", line 757, in _auth\n",
      "    self._transport.auth_publickey(username, key)\n",
      "  File \"/home/ucl/modl/yimzhang/miniforge3/envs/aiida-240/lib/python3.11/site-packages/paramiko/transport.py\", line 1635, in auth_publickey\n",
      "    return self.auth_handler.wait_for_response(my_event)\n",
      "           ^^^^^^^^^^^^^^^^^^^^^^^^^^^^^^^^^^^^^^^^^^^^^\n",
      "  File \"/home/ucl/modl/yimzhang/miniforge3/envs/aiida-240/lib/python3.11/site-packages/paramiko/auth_handler.py\", line 259, in wait_for_response\n",
      "    raise e\n",
      "paramiko.ssh_exception.AuthenticationException: Authentication failed.\n",
      "04/28/2025 03:21:22 PM <885922> aiida.engine.transports: [ERROR] Exception whilst using transport:\n",
      "Traceback (most recent call last):\n",
      "  File \"/home/ucl/modl/yimzhang/miniforge3/envs/aiida-240/lib/python3.11/site-packages/aiida/engine/transports.py\", line 106, in request_transport\n",
      "    yield transport_request.future\n",
      "  File \"/home/ucl/modl/yimzhang/miniforge3/envs/aiida-240/lib/python3.11/site-packages/aiida/engine/processes/calcjobs/tasks.py\", line 426, in do_kill\n",
      "    transport = await cancellable.with_interrupt(request)\n",
      "                ^^^^^^^^^^^^^^^^^^^^^^^^^^^^^^^^^^^^^^^^^\n",
      "  File \"/home/ucl/modl/yimzhang/miniforge3/envs/aiida-240/lib/python3.11/site-packages/aiida/engine/utils.py\", line 115, in with_interrupt\n",
      "    result = await next(wait_iter)\n",
      "             ^^^^^^^^^^^^^^^^^^^^^\n",
      "  File \"/home/ucl/modl/yimzhang/miniforge3/envs/aiida-240/lib/python3.11/asyncio/tasks.py\", line 605, in _wait_for_one\n",
      "    return f.result()  # May raise f.exception().\n",
      "           ^^^^^^^^^^\n",
      "  File \"/home/ucl/modl/yimzhang/miniforge3/envs/aiida-240/lib/python3.11/asyncio/futures.py\", line 203, in result\n",
      "    raise self._exception.with_traceback(self._exception_tb)\n",
      "  File \"/home/ucl/modl/yimzhang/miniforge3/envs/aiida-240/lib/python3.11/site-packages/aiida/engine/transports.py\", line 87, in do_open\n",
      "    transport.open()\n",
      "  File \"/home/ucl/modl/yimzhang/miniforge3/envs/aiida-240/lib/python3.11/site-packages/aiida/transports/plugins/ssh.py\", line 480, in open\n",
      "    proxy_client.connect(proxy['host'], **proxy_connargs)\n",
      "  File \"/home/ucl/modl/yimzhang/miniforge3/envs/aiida-240/lib/python3.11/site-packages/paramiko/client.py\", line 450, in connect\n",
      "    self._auth(\n",
      "  File \"/home/ucl/modl/yimzhang/miniforge3/envs/aiida-240/lib/python3.11/site-packages/paramiko/client.py\", line 781, in _auth\n",
      "    raise saved_exception\n",
      "  File \"/home/ucl/modl/yimzhang/miniforge3/envs/aiida-240/lib/python3.11/site-packages/paramiko/client.py\", line 757, in _auth\n",
      "    self._transport.auth_publickey(username, key)\n",
      "  File \"/home/ucl/modl/yimzhang/miniforge3/envs/aiida-240/lib/python3.11/site-packages/paramiko/transport.py\", line 1635, in auth_publickey\n",
      "    return self.auth_handler.wait_for_response(my_event)\n",
      "           ^^^^^^^^^^^^^^^^^^^^^^^^^^^^^^^^^^^^^^^^^^^^^\n",
      "  File \"/home/ucl/modl/yimzhang/miniforge3/envs/aiida-240/lib/python3.11/site-packages/paramiko/auth_handler.py\", line 259, in wait_for_response\n",
      "    raise e\n",
      "paramiko.ssh_exception.AuthenticationException: Authentication failed.\n",
      "\n",
      "04/28/2025 03:21:22 PM <885922> aiida.orm.nodes.process.calculation.calcjob.CalcJobNode: [ERROR] iteration 3 of do_kill excepted, retrying after 80 seconds\n",
      "Traceback (most recent call last):\n",
      "  File \"/home/ucl/modl/yimzhang/miniforge3/envs/aiida-240/lib/python3.11/site-packages/aiida/engine/utils.py\", line 205, in exponential_backoff_retry\n",
      "    result = await coro()\n",
      "             ^^^^^^^^^^^^\n",
      "  File \"/home/ucl/modl/yimzhang/miniforge3/envs/aiida-240/lib/python3.11/site-packages/aiida/engine/processes/calcjobs/tasks.py\", line 426, in do_kill\n",
      "    transport = await cancellable.with_interrupt(request)\n",
      "                ^^^^^^^^^^^^^^^^^^^^^^^^^^^^^^^^^^^^^^^^^\n",
      "  File \"/home/ucl/modl/yimzhang/miniforge3/envs/aiida-240/lib/python3.11/site-packages/aiida/engine/utils.py\", line 115, in with_interrupt\n",
      "    result = await next(wait_iter)\n",
      "             ^^^^^^^^^^^^^^^^^^^^^\n",
      "  File \"/home/ucl/modl/yimzhang/miniforge3/envs/aiida-240/lib/python3.11/asyncio/tasks.py\", line 605, in _wait_for_one\n",
      "    return f.result()  # May raise f.exception().\n",
      "           ^^^^^^^^^^\n",
      "  File \"/home/ucl/modl/yimzhang/miniforge3/envs/aiida-240/lib/python3.11/asyncio/futures.py\", line 203, in result\n",
      "    raise self._exception.with_traceback(self._exception_tb)\n",
      "  File \"/home/ucl/modl/yimzhang/miniforge3/envs/aiida-240/lib/python3.11/site-packages/aiida/engine/transports.py\", line 87, in do_open\n",
      "    transport.open()\n",
      "  File \"/home/ucl/modl/yimzhang/miniforge3/envs/aiida-240/lib/python3.11/site-packages/aiida/transports/plugins/ssh.py\", line 480, in open\n",
      "    proxy_client.connect(proxy['host'], **proxy_connargs)\n",
      "  File \"/home/ucl/modl/yimzhang/miniforge3/envs/aiida-240/lib/python3.11/site-packages/paramiko/client.py\", line 450, in connect\n",
      "    self._auth(\n",
      "  File \"/home/ucl/modl/yimzhang/miniforge3/envs/aiida-240/lib/python3.11/site-packages/paramiko/client.py\", line 781, in _auth\n",
      "    raise saved_exception\n",
      "  File \"/home/ucl/modl/yimzhang/miniforge3/envs/aiida-240/lib/python3.11/site-packages/paramiko/client.py\", line 757, in _auth\n",
      "    self._transport.auth_publickey(username, key)\n",
      "  File \"/home/ucl/modl/yimzhang/miniforge3/envs/aiida-240/lib/python3.11/site-packages/paramiko/transport.py\", line 1635, in auth_publickey\n",
      "    return self.auth_handler.wait_for_response(my_event)\n",
      "           ^^^^^^^^^^^^^^^^^^^^^^^^^^^^^^^^^^^^^^^^^^^^^\n",
      "  File \"/home/ucl/modl/yimzhang/miniforge3/envs/aiida-240/lib/python3.11/site-packages/paramiko/auth_handler.py\", line 259, in wait_for_response\n",
      "    raise e\n",
      "paramiko.ssh_exception.AuthenticationException: Authentication failed.\n",
      "04/28/2025 03:23:12 PM <885922> aiida.engine.transports: [ERROR] Exception whilst using transport:\n",
      "Traceback (most recent call last):\n",
      "  File \"/home/ucl/modl/yimzhang/miniforge3/envs/aiida-240/lib/python3.11/site-packages/aiida/engine/transports.py\", line 106, in request_transport\n",
      "    yield transport_request.future\n",
      "  File \"/home/ucl/modl/yimzhang/miniforge3/envs/aiida-240/lib/python3.11/site-packages/aiida/engine/processes/calcjobs/tasks.py\", line 426, in do_kill\n",
      "    transport = await cancellable.with_interrupt(request)\n",
      "                ^^^^^^^^^^^^^^^^^^^^^^^^^^^^^^^^^^^^^^^^^\n",
      "  File \"/home/ucl/modl/yimzhang/miniforge3/envs/aiida-240/lib/python3.11/site-packages/aiida/engine/utils.py\", line 115, in with_interrupt\n",
      "    result = await next(wait_iter)\n",
      "             ^^^^^^^^^^^^^^^^^^^^^\n",
      "  File \"/home/ucl/modl/yimzhang/miniforge3/envs/aiida-240/lib/python3.11/asyncio/tasks.py\", line 605, in _wait_for_one\n",
      "    return f.result()  # May raise f.exception().\n",
      "           ^^^^^^^^^^\n",
      "  File \"/home/ucl/modl/yimzhang/miniforge3/envs/aiida-240/lib/python3.11/asyncio/futures.py\", line 203, in result\n",
      "    raise self._exception.with_traceback(self._exception_tb)\n",
      "  File \"/home/ucl/modl/yimzhang/miniforge3/envs/aiida-240/lib/python3.11/site-packages/aiida/engine/transports.py\", line 87, in do_open\n",
      "    transport.open()\n",
      "  File \"/home/ucl/modl/yimzhang/miniforge3/envs/aiida-240/lib/python3.11/site-packages/aiida/transports/plugins/ssh.py\", line 480, in open\n",
      "    proxy_client.connect(proxy['host'], **proxy_connargs)\n",
      "  File \"/home/ucl/modl/yimzhang/miniforge3/envs/aiida-240/lib/python3.11/site-packages/paramiko/client.py\", line 450, in connect\n",
      "    self._auth(\n",
      "  File \"/home/ucl/modl/yimzhang/miniforge3/envs/aiida-240/lib/python3.11/site-packages/paramiko/client.py\", line 781, in _auth\n",
      "    raise saved_exception\n",
      "  File \"/home/ucl/modl/yimzhang/miniforge3/envs/aiida-240/lib/python3.11/site-packages/paramiko/client.py\", line 757, in _auth\n",
      "    self._transport.auth_publickey(username, key)\n",
      "  File \"/home/ucl/modl/yimzhang/miniforge3/envs/aiida-240/lib/python3.11/site-packages/paramiko/transport.py\", line 1635, in auth_publickey\n",
      "    return self.auth_handler.wait_for_response(my_event)\n",
      "           ^^^^^^^^^^^^^^^^^^^^^^^^^^^^^^^^^^^^^^^^^^^^^\n",
      "  File \"/home/ucl/modl/yimzhang/miniforge3/envs/aiida-240/lib/python3.11/site-packages/paramiko/auth_handler.py\", line 259, in wait_for_response\n",
      "    raise e\n",
      "paramiko.ssh_exception.AuthenticationException: Authentication failed.\n",
      "\n",
      "04/28/2025 03:23:12 PM <885922> aiida.orm.nodes.process.calculation.calcjob.CalcJobNode: [ERROR] iteration 4 of do_kill excepted, retrying after 160 seconds\n",
      "Traceback (most recent call last):\n",
      "  File \"/home/ucl/modl/yimzhang/miniforge3/envs/aiida-240/lib/python3.11/site-packages/aiida/engine/utils.py\", line 205, in exponential_backoff_retry\n",
      "    result = await coro()\n",
      "             ^^^^^^^^^^^^\n",
      "  File \"/home/ucl/modl/yimzhang/miniforge3/envs/aiida-240/lib/python3.11/site-packages/aiida/engine/processes/calcjobs/tasks.py\", line 426, in do_kill\n",
      "    transport = await cancellable.with_interrupt(request)\n",
      "                ^^^^^^^^^^^^^^^^^^^^^^^^^^^^^^^^^^^^^^^^^\n",
      "  File \"/home/ucl/modl/yimzhang/miniforge3/envs/aiida-240/lib/python3.11/site-packages/aiida/engine/utils.py\", line 115, in with_interrupt\n",
      "    result = await next(wait_iter)\n",
      "             ^^^^^^^^^^^^^^^^^^^^^\n",
      "  File \"/home/ucl/modl/yimzhang/miniforge3/envs/aiida-240/lib/python3.11/asyncio/tasks.py\", line 605, in _wait_for_one\n",
      "    return f.result()  # May raise f.exception().\n",
      "           ^^^^^^^^^^\n",
      "  File \"/home/ucl/modl/yimzhang/miniforge3/envs/aiida-240/lib/python3.11/asyncio/futures.py\", line 203, in result\n",
      "    raise self._exception.with_traceback(self._exception_tb)\n",
      "  File \"/home/ucl/modl/yimzhang/miniforge3/envs/aiida-240/lib/python3.11/site-packages/aiida/engine/transports.py\", line 87, in do_open\n",
      "    transport.open()\n",
      "  File \"/home/ucl/modl/yimzhang/miniforge3/envs/aiida-240/lib/python3.11/site-packages/aiida/transports/plugins/ssh.py\", line 480, in open\n",
      "    proxy_client.connect(proxy['host'], **proxy_connargs)\n",
      "  File \"/home/ucl/modl/yimzhang/miniforge3/envs/aiida-240/lib/python3.11/site-packages/paramiko/client.py\", line 450, in connect\n",
      "    self._auth(\n",
      "  File \"/home/ucl/modl/yimzhang/miniforge3/envs/aiida-240/lib/python3.11/site-packages/paramiko/client.py\", line 781, in _auth\n",
      "    raise saved_exception\n",
      "  File \"/home/ucl/modl/yimzhang/miniforge3/envs/aiida-240/lib/python3.11/site-packages/paramiko/client.py\", line 757, in _auth\n",
      "    self._transport.auth_publickey(username, key)\n",
      "  File \"/home/ucl/modl/yimzhang/miniforge3/envs/aiida-240/lib/python3.11/site-packages/paramiko/transport.py\", line 1635, in auth_publickey\n",
      "    return self.auth_handler.wait_for_response(my_event)\n",
      "           ^^^^^^^^^^^^^^^^^^^^^^^^^^^^^^^^^^^^^^^^^^^^^\n",
      "  File \"/home/ucl/modl/yimzhang/miniforge3/envs/aiida-240/lib/python3.11/site-packages/paramiko/auth_handler.py\", line 259, in wait_for_response\n",
      "    raise e\n",
      "paramiko.ssh_exception.AuthenticationException: Authentication failed.\n",
      "04/28/2025 03:26:22 PM <885922> aiida.engine.transports: [ERROR] Exception whilst using transport:\n",
      "Traceback (most recent call last):\n",
      "  File \"/home/ucl/modl/yimzhang/miniforge3/envs/aiida-240/lib/python3.11/site-packages/aiida/engine/transports.py\", line 106, in request_transport\n",
      "    yield transport_request.future\n",
      "  File \"/home/ucl/modl/yimzhang/miniforge3/envs/aiida-240/lib/python3.11/site-packages/aiida/engine/processes/calcjobs/tasks.py\", line 426, in do_kill\n",
      "    transport = await cancellable.with_interrupt(request)\n",
      "                ^^^^^^^^^^^^^^^^^^^^^^^^^^^^^^^^^^^^^^^^^\n",
      "  File \"/home/ucl/modl/yimzhang/miniforge3/envs/aiida-240/lib/python3.11/site-packages/aiida/engine/utils.py\", line 115, in with_interrupt\n",
      "    result = await next(wait_iter)\n",
      "             ^^^^^^^^^^^^^^^^^^^^^\n",
      "  File \"/home/ucl/modl/yimzhang/miniforge3/envs/aiida-240/lib/python3.11/asyncio/tasks.py\", line 605, in _wait_for_one\n",
      "    return f.result()  # May raise f.exception().\n",
      "           ^^^^^^^^^^\n",
      "  File \"/home/ucl/modl/yimzhang/miniforge3/envs/aiida-240/lib/python3.11/asyncio/futures.py\", line 203, in result\n",
      "    raise self._exception.with_traceback(self._exception_tb)\n",
      "  File \"/home/ucl/modl/yimzhang/miniforge3/envs/aiida-240/lib/python3.11/site-packages/aiida/engine/transports.py\", line 87, in do_open\n",
      "    transport.open()\n",
      "  File \"/home/ucl/modl/yimzhang/miniforge3/envs/aiida-240/lib/python3.11/site-packages/aiida/transports/plugins/ssh.py\", line 480, in open\n",
      "    proxy_client.connect(proxy['host'], **proxy_connargs)\n",
      "  File \"/home/ucl/modl/yimzhang/miniforge3/envs/aiida-240/lib/python3.11/site-packages/paramiko/client.py\", line 450, in connect\n",
      "    self._auth(\n",
      "  File \"/home/ucl/modl/yimzhang/miniforge3/envs/aiida-240/lib/python3.11/site-packages/paramiko/client.py\", line 781, in _auth\n",
      "    raise saved_exception\n",
      "  File \"/home/ucl/modl/yimzhang/miniforge3/envs/aiida-240/lib/python3.11/site-packages/paramiko/client.py\", line 757, in _auth\n",
      "    self._transport.auth_publickey(username, key)\n",
      "  File \"/home/ucl/modl/yimzhang/miniforge3/envs/aiida-240/lib/python3.11/site-packages/paramiko/transport.py\", line 1635, in auth_publickey\n",
      "    return self.auth_handler.wait_for_response(my_event)\n",
      "           ^^^^^^^^^^^^^^^^^^^^^^^^^^^^^^^^^^^^^^^^^^^^^\n",
      "  File \"/home/ucl/modl/yimzhang/miniforge3/envs/aiida-240/lib/python3.11/site-packages/paramiko/auth_handler.py\", line 259, in wait_for_response\n",
      "    raise e\n",
      "paramiko.ssh_exception.AuthenticationException: Authentication failed.\n",
      "\n",
      "04/28/2025 03:26:22 PM <885922> aiida.orm.nodes.process.calculation.calcjob.CalcJobNode: [ERROR] iteration 5 of do_kill excepted\n",
      "Traceback (most recent call last):\n",
      "  File \"/home/ucl/modl/yimzhang/miniforge3/envs/aiida-240/lib/python3.11/site-packages/aiida/engine/utils.py\", line 205, in exponential_backoff_retry\n",
      "    result = await coro()\n",
      "             ^^^^^^^^^^^^\n",
      "  File \"/home/ucl/modl/yimzhang/miniforge3/envs/aiida-240/lib/python3.11/site-packages/aiida/engine/processes/calcjobs/tasks.py\", line 426, in do_kill\n",
      "    transport = await cancellable.with_interrupt(request)\n",
      "                ^^^^^^^^^^^^^^^^^^^^^^^^^^^^^^^^^^^^^^^^^\n",
      "  File \"/home/ucl/modl/yimzhang/miniforge3/envs/aiida-240/lib/python3.11/site-packages/aiida/engine/utils.py\", line 115, in with_interrupt\n",
      "    result = await next(wait_iter)\n",
      "             ^^^^^^^^^^^^^^^^^^^^^\n",
      "  File \"/home/ucl/modl/yimzhang/miniforge3/envs/aiida-240/lib/python3.11/asyncio/tasks.py\", line 605, in _wait_for_one\n",
      "    return f.result()  # May raise f.exception().\n",
      "           ^^^^^^^^^^\n",
      "  File \"/home/ucl/modl/yimzhang/miniforge3/envs/aiida-240/lib/python3.11/asyncio/futures.py\", line 203, in result\n",
      "    raise self._exception.with_traceback(self._exception_tb)\n",
      "  File \"/home/ucl/modl/yimzhang/miniforge3/envs/aiida-240/lib/python3.11/site-packages/aiida/engine/transports.py\", line 87, in do_open\n",
      "    transport.open()\n",
      "  File \"/home/ucl/modl/yimzhang/miniforge3/envs/aiida-240/lib/python3.11/site-packages/aiida/transports/plugins/ssh.py\", line 480, in open\n",
      "    proxy_client.connect(proxy['host'], **proxy_connargs)\n",
      "  File \"/home/ucl/modl/yimzhang/miniforge3/envs/aiida-240/lib/python3.11/site-packages/paramiko/client.py\", line 450, in connect\n",
      "    self._auth(\n",
      "  File \"/home/ucl/modl/yimzhang/miniforge3/envs/aiida-240/lib/python3.11/site-packages/paramiko/client.py\", line 781, in _auth\n",
      "    raise saved_exception\n",
      "  File \"/home/ucl/modl/yimzhang/miniforge3/envs/aiida-240/lib/python3.11/site-packages/paramiko/client.py\", line 757, in _auth\n",
      "    self._transport.auth_publickey(username, key)\n",
      "  File \"/home/ucl/modl/yimzhang/miniforge3/envs/aiida-240/lib/python3.11/site-packages/paramiko/transport.py\", line 1635, in auth_publickey\n",
      "    return self.auth_handler.wait_for_response(my_event)\n",
      "           ^^^^^^^^^^^^^^^^^^^^^^^^^^^^^^^^^^^^^^^^^^^^^\n",
      "  File \"/home/ucl/modl/yimzhang/miniforge3/envs/aiida-240/lib/python3.11/site-packages/paramiko/auth_handler.py\", line 259, in wait_for_response\n",
      "    raise e\n",
      "paramiko.ssh_exception.AuthenticationException: Authentication failed.\n",
      "04/28/2025 03:26:22 PM <885922> aiida.orm.nodes.process.calculation.calcjob.CalcJobNode: [WARNING] maximum attempts 5 of calling do_kill, exceeded\n",
      "04/28/2025 03:26:22 PM <885922> aiida.engine.processes.calcjobs.tasks: [WARNING] killing CalcJob<71901> failed\n",
      "04/28/2025 03:26:22 PM <885922> aiida.orm.nodes.process.calculation.calcjob.CalcJobNode: [REPORT] [71901|PwCalculation|on_except]: Traceback (most recent call last):\n",
      "  File \"/home/ucl/modl/yimzhang/miniforge3/envs/aiida-240/lib/python3.11/site-packages/aiida/engine/utils.py\", line 205, in exponential_backoff_retry\n",
      "    result = await coro()\n",
      "             ^^^^^^^^^^^^\n",
      "  File \"/home/ucl/modl/yimzhang/miniforge3/envs/aiida-240/lib/python3.11/site-packages/aiida/engine/processes/calcjobs/tasks.py\", line 426, in do_kill\n",
      "    transport = await cancellable.with_interrupt(request)\n",
      "                ^^^^^^^^^^^^^^^^^^^^^^^^^^^^^^^^^^^^^^^^^\n",
      "  File \"/home/ucl/modl/yimzhang/miniforge3/envs/aiida-240/lib/python3.11/site-packages/aiida/engine/utils.py\", line 115, in with_interrupt\n",
      "    result = await next(wait_iter)\n",
      "             ^^^^^^^^^^^^^^^^^^^^^\n",
      "  File \"/home/ucl/modl/yimzhang/miniforge3/envs/aiida-240/lib/python3.11/asyncio/tasks.py\", line 605, in _wait_for_one\n",
      "    return f.result()  # May raise f.exception().\n",
      "           ^^^^^^^^^^\n",
      "  File \"/home/ucl/modl/yimzhang/miniforge3/envs/aiida-240/lib/python3.11/asyncio/futures.py\", line 203, in result\n",
      "    raise self._exception.with_traceback(self._exception_tb)\n",
      "  File \"/home/ucl/modl/yimzhang/miniforge3/envs/aiida-240/lib/python3.11/site-packages/aiida/engine/transports.py\", line 87, in do_open\n",
      "    transport.open()\n",
      "  File \"/home/ucl/modl/yimzhang/miniforge3/envs/aiida-240/lib/python3.11/site-packages/aiida/transports/plugins/ssh.py\", line 480, in open\n",
      "    proxy_client.connect(proxy['host'], **proxy_connargs)\n",
      "  File \"/home/ucl/modl/yimzhang/miniforge3/envs/aiida-240/lib/python3.11/site-packages/paramiko/client.py\", line 450, in connect\n",
      "    self._auth(\n",
      "  File \"/home/ucl/modl/yimzhang/miniforge3/envs/aiida-240/lib/python3.11/site-packages/paramiko/client.py\", line 781, in _auth\n",
      "    raise saved_exception\n",
      "  File \"/home/ucl/modl/yimzhang/miniforge3/envs/aiida-240/lib/python3.11/site-packages/paramiko/client.py\", line 757, in _auth\n",
      "    self._transport.auth_publickey(username, key)\n",
      "  File \"/home/ucl/modl/yimzhang/miniforge3/envs/aiida-240/lib/python3.11/site-packages/paramiko/transport.py\", line 1635, in auth_publickey\n",
      "    return self.auth_handler.wait_for_response(my_event)\n",
      "           ^^^^^^^^^^^^^^^^^^^^^^^^^^^^^^^^^^^^^^^^^^^^^\n",
      "  File \"/home/ucl/modl/yimzhang/miniforge3/envs/aiida-240/lib/python3.11/site-packages/paramiko/auth_handler.py\", line 259, in wait_for_response\n",
      "    raise e\n",
      "paramiko.ssh_exception.AuthenticationException: Authentication failed.\n",
      "\n",
      "The above exception was the direct cause of the following exception:\n",
      "\n",
      "Traceback (most recent call last):\n",
      "  File \"/home/ucl/modl/yimzhang/miniforge3/envs/aiida-240/lib/python3.11/site-packages/plumpy/processes.py\", line 1218, in step\n",
      "    next_state = await self._run_task(self._state.execute)\n",
      "                 ^^^^^^^^^^^^^^^^^^^^^^^^^^^^^^^^^^^^^^^^^\n",
      "  File \"/home/ucl/modl/yimzhang/miniforge3/envs/aiida-240/lib/python3.11/site-packages/plumpy/processes.py\", line 567, in _run_task\n",
      "    result = await coro(*args, **kwargs)\n",
      "             ^^^^^^^^^^^^^^^^^^^^^^^^^^^\n",
      "  File \"/home/ucl/modl/yimzhang/miniforge3/envs/aiida-240/lib/python3.11/site-packages/aiida/engine/processes/calcjobs/tasks.py\", line 570, in execute\n",
      "    await self._kill_job(node, transport_queue)\n",
      "  File \"/home/ucl/modl/yimzhang/miniforge3/envs/aiida-240/lib/python3.11/site-packages/aiida/engine/processes/calcjobs/tasks.py\", line 623, in _launch_task\n",
      "    result = await self._task\n",
      "             ^^^^^^^^^^^^^^^^\n",
      "  File \"/home/ucl/modl/yimzhang/miniforge3/envs/aiida-240/lib/python3.11/asyncio/tasks.py\", line 339, in __wakeup\n",
      "    future.result()\n",
      "  File \"/home/ucl/modl/yimzhang/miniforge3/envs/aiida-240/lib/python3.11/site-packages/aiida/engine/utils.py\", line 137, in execute_coroutine\n",
      "    result = await coro(future)\n",
      "             ^^^^^^^^^^^^^^^^^^\n",
      "  File \"/home/ucl/modl/yimzhang/miniforge3/envs/aiida-240/lib/python3.11/site-packages/aiida/engine/processes/calcjobs/tasks.py\", line 436, in task_kill_job\n",
      "    raise TransportTaskException(f'kill_calculation failed {max_attempts} times consecutively') from exception\n",
      "aiida.common.exceptions.TransportTaskException: kill_calculation failed 5 times consecutively\n",
      "\n"
     ]
    }
   ],
   "source": [
    "inputs['skip_uc'] = orm.Bool(False)\n",
    "inputs['n_layers'] =orm.Int(16)\n",
    "inputs['slipping_system'] = orm.List(['A2', '100'])\n",
    "\n",
    "logging.getLogger('aiida.transport.SshTransport') .setLevel(logging.ERROR)\n",
    "logging.getLogger('aiida.scheduler.slurm').setLevel(logging.ERROR)\n",
    "\n",
    "test_node = run.get_node(USFWorkChain, **inputs)\n",
    "test_USF_group.add_nodes(test_node.node)"
   ]
  },
  {
   "cell_type": "markdown",
   "metadata": {},
   "source": [
    "## {110} surface"
   ]
  },
  {
   "cell_type": "code",
   "execution_count": 23,
   "metadata": {},
   "outputs": [
    {
     "name": "stderr",
     "output_type": "stream",
     "text": [
      "04/28/2025 03:27:28 PM <885922> aiida.orm.nodes.process.workflow.workchain.WorkChainNode: [REPORT] [71930|USFWorkChain|validate_slipping_system]: FCC element crystal <space group #227, prototype V>. I don't know the usual gliding plane. \n",
      "04/28/2025 03:27:28 PM <885922> aiida.orm.nodes.process.workflow.workchain.WorkChainNode: [REPORT] [71930|USFWorkChain|validate_slipping_system]: Now we are working on 110 gliding plane.\n",
      "04/28/2025 03:27:28 PM <885922> aiida.orm.nodes.process.workflow.workchain.WorkChainNode: [REPORT] [71930|USFWorkChain|validate_slipping_system]: Faulting is possible for 110 gliding plane.The stacking order is AB. Slipping direction: 1/2[001]. \n",
      "04/28/2025 03:27:28 PM <885922> aiida.orm.nodes.process.workflow.workchain.WorkChainNode: [REPORT] [71930|USFWorkChain|run_scf]: launching PwCalculation<71931> for V unit cell geometry.\n",
      "04/28/2025 03:27:32 PM <885922> aiida.transport.SshTransport: [ERROR] Error connecting to proxy 'gwceci.cism.ucl.ac.be' through SSH: [SshTransport] Authentication failed., connect_args were: {'username': 'yimzhang', 'port': 22, 'look_for_keys': True, 'key_filename': '/home/ucl/modl/yimzhang/.ssh/id_rsa.ceci', 'timeout': 60, 'allow_agent': True, 'compress': True, 'gss_auth': False, 'gss_kex': False, 'gss_deleg_creds': False, 'gss_host': 'frontal.lucia.cenaero.be'}\n",
      "04/28/2025 03:27:32 PM <885922> aiida.engine.transports: [ERROR] exception occurred while trying to open transport:\n",
      " Authentication failed.\n",
      "04/28/2025 03:27:32 PM <885922> aiida.engine.transports: [ERROR] Exception whilst using transport:\n",
      "Traceback (most recent call last):\n",
      "  File \"/home/ucl/modl/yimzhang/miniforge3/envs/aiida-240/lib/python3.11/site-packages/aiida/engine/transports.py\", line 106, in request_transport\n",
      "    yield transport_request.future\n",
      "  File \"/home/ucl/modl/yimzhang/miniforge3/envs/aiida-240/lib/python3.11/site-packages/aiida/engine/processes/calcjobs/tasks.py\", line 86, in do_upload\n",
      "    transport = await cancellable.with_interrupt(request)\n",
      "                ^^^^^^^^^^^^^^^^^^^^^^^^^^^^^^^^^^^^^^^^^\n",
      "  File \"/home/ucl/modl/yimzhang/miniforge3/envs/aiida-240/lib/python3.11/site-packages/aiida/engine/utils.py\", line 115, in with_interrupt\n",
      "    result = await next(wait_iter)\n",
      "             ^^^^^^^^^^^^^^^^^^^^^\n",
      "  File \"/home/ucl/modl/yimzhang/miniforge3/envs/aiida-240/lib/python3.11/asyncio/tasks.py\", line 605, in _wait_for_one\n",
      "    return f.result()  # May raise f.exception().\n",
      "           ^^^^^^^^^^\n",
      "  File \"/home/ucl/modl/yimzhang/miniforge3/envs/aiida-240/lib/python3.11/asyncio/futures.py\", line 203, in result\n",
      "    raise self._exception.with_traceback(self._exception_tb)\n",
      "  File \"/home/ucl/modl/yimzhang/miniforge3/envs/aiida-240/lib/python3.11/site-packages/aiida/engine/transports.py\", line 87, in do_open\n",
      "    transport.open()\n",
      "  File \"/home/ucl/modl/yimzhang/miniforge3/envs/aiida-240/lib/python3.11/site-packages/aiida/transports/plugins/ssh.py\", line 480, in open\n",
      "    proxy_client.connect(proxy['host'], **proxy_connargs)\n",
      "  File \"/home/ucl/modl/yimzhang/miniforge3/envs/aiida-240/lib/python3.11/site-packages/paramiko/client.py\", line 450, in connect\n",
      "    self._auth(\n",
      "  File \"/home/ucl/modl/yimzhang/miniforge3/envs/aiida-240/lib/python3.11/site-packages/paramiko/client.py\", line 781, in _auth\n",
      "    raise saved_exception\n",
      "  File \"/home/ucl/modl/yimzhang/miniforge3/envs/aiida-240/lib/python3.11/site-packages/paramiko/client.py\", line 757, in _auth\n",
      "    self._transport.auth_publickey(username, key)\n",
      "  File \"/home/ucl/modl/yimzhang/miniforge3/envs/aiida-240/lib/python3.11/site-packages/paramiko/transport.py\", line 1635, in auth_publickey\n",
      "    return self.auth_handler.wait_for_response(my_event)\n",
      "           ^^^^^^^^^^^^^^^^^^^^^^^^^^^^^^^^^^^^^^^^^^^^^\n",
      "  File \"/home/ucl/modl/yimzhang/miniforge3/envs/aiida-240/lib/python3.11/site-packages/paramiko/auth_handler.py\", line 259, in wait_for_response\n",
      "    raise e\n",
      "paramiko.ssh_exception.AuthenticationException: Authentication failed.\n",
      "\n",
      "04/28/2025 03:27:32 PM <885922> aiida.orm.nodes.process.calculation.calcjob.CalcJobNode: [ERROR] iteration 1 of do_upload excepted, retrying after 20 seconds\n",
      "Traceback (most recent call last):\n",
      "  File \"/home/ucl/modl/yimzhang/miniforge3/envs/aiida-240/lib/python3.11/site-packages/aiida/engine/utils.py\", line 205, in exponential_backoff_retry\n",
      "    result = await coro()\n",
      "             ^^^^^^^^^^^^\n",
      "  File \"/home/ucl/modl/yimzhang/miniforge3/envs/aiida-240/lib/python3.11/site-packages/aiida/engine/processes/calcjobs/tasks.py\", line 86, in do_upload\n",
      "    transport = await cancellable.with_interrupt(request)\n",
      "                ^^^^^^^^^^^^^^^^^^^^^^^^^^^^^^^^^^^^^^^^^\n",
      "  File \"/home/ucl/modl/yimzhang/miniforge3/envs/aiida-240/lib/python3.11/site-packages/aiida/engine/utils.py\", line 115, in with_interrupt\n",
      "    result = await next(wait_iter)\n",
      "             ^^^^^^^^^^^^^^^^^^^^^\n",
      "  File \"/home/ucl/modl/yimzhang/miniforge3/envs/aiida-240/lib/python3.11/asyncio/tasks.py\", line 605, in _wait_for_one\n",
      "    return f.result()  # May raise f.exception().\n",
      "           ^^^^^^^^^^\n",
      "  File \"/home/ucl/modl/yimzhang/miniforge3/envs/aiida-240/lib/python3.11/asyncio/futures.py\", line 203, in result\n",
      "    raise self._exception.with_traceback(self._exception_tb)\n",
      "  File \"/home/ucl/modl/yimzhang/miniforge3/envs/aiida-240/lib/python3.11/site-packages/aiida/engine/transports.py\", line 87, in do_open\n",
      "    transport.open()\n",
      "  File \"/home/ucl/modl/yimzhang/miniforge3/envs/aiida-240/lib/python3.11/site-packages/aiida/transports/plugins/ssh.py\", line 480, in open\n",
      "    proxy_client.connect(proxy['host'], **proxy_connargs)\n",
      "  File \"/home/ucl/modl/yimzhang/miniforge3/envs/aiida-240/lib/python3.11/site-packages/paramiko/client.py\", line 450, in connect\n",
      "    self._auth(\n",
      "  File \"/home/ucl/modl/yimzhang/miniforge3/envs/aiida-240/lib/python3.11/site-packages/paramiko/client.py\", line 781, in _auth\n",
      "    raise saved_exception\n",
      "  File \"/home/ucl/modl/yimzhang/miniforge3/envs/aiida-240/lib/python3.11/site-packages/paramiko/client.py\", line 757, in _auth\n",
      "    self._transport.auth_publickey(username, key)\n",
      "  File \"/home/ucl/modl/yimzhang/miniforge3/envs/aiida-240/lib/python3.11/site-packages/paramiko/transport.py\", line 1635, in auth_publickey\n",
      "    return self.auth_handler.wait_for_response(my_event)\n",
      "           ^^^^^^^^^^^^^^^^^^^^^^^^^^^^^^^^^^^^^^^^^^^^^\n",
      "  File \"/home/ucl/modl/yimzhang/miniforge3/envs/aiida-240/lib/python3.11/site-packages/paramiko/auth_handler.py\", line 259, in wait_for_response\n",
      "    raise e\n",
      "paramiko.ssh_exception.AuthenticationException: Authentication failed.\n",
      "04/28/2025 03:27:55 PM <885922> aiida.engine.runners: [CRITICAL] runner received interrupt, killing process 71930\n",
      "04/28/2025 03:27:55 PM <885922> aiida.orm.nodes.process.workflow.workchain.WorkChainNode: [REPORT] [71930|USFWorkChain|on_terminated]: remote folders will not be cleaned\n"
     ]
    },
    {
     "ename": "KilledError",
     "evalue": "Process was killed because the runner received an interrupt",
     "output_type": "error",
     "traceback": [
      "\u001b[31m---------------------------------------------------------------------------\u001b[39m",
      "\u001b[31mKilledError\u001b[39m                               Traceback (most recent call last)",
      "\u001b[36mCell\u001b[39m\u001b[36m \u001b[39m\u001b[32mIn[23]\u001b[39m\u001b[32m, line 8\u001b[39m\n\u001b[32m      5\u001b[39m logging.getLogger(\u001b[33m'\u001b[39m\u001b[33maiida.transport.SshTransport\u001b[39m\u001b[33m'\u001b[39m) .setLevel(logging.ERROR)\n\u001b[32m      6\u001b[39m logging.getLogger(\u001b[33m'\u001b[39m\u001b[33maiida.scheduler.slurm\u001b[39m\u001b[33m'\u001b[39m).setLevel(logging.ERROR)\n\u001b[32m----> \u001b[39m\u001b[32m8\u001b[39m test_node = \u001b[43mrun\u001b[49m\u001b[43m.\u001b[49m\u001b[43mget_node\u001b[49m\u001b[43m(\u001b[49m\u001b[43mUSFWorkChain\u001b[49m\u001b[43m,\u001b[49m\u001b[43m \u001b[49m\u001b[43m*\u001b[49m\u001b[43m*\u001b[49m\u001b[43minputs\u001b[49m\u001b[43m)\u001b[49m\n\u001b[32m      9\u001b[39m test_USF_group.add_nodes(test_node.node)\n",
      "\u001b[36mFile \u001b[39m\u001b[32m~/miniforge3/envs/aiida-240/lib/python3.11/site-packages/aiida/engine/launch.py:65\u001b[39m, in \u001b[36mrun_get_node\u001b[39m\u001b[34m(process, inputs, **kwargs)\u001b[39m\n\u001b[32m     62\u001b[39m \u001b[38;5;28;01melse\u001b[39;00m:\n\u001b[32m     63\u001b[39m     runner = manager.get_manager().get_runner()\n\u001b[32m---> \u001b[39m\u001b[32m65\u001b[39m \u001b[38;5;28;01mreturn\u001b[39;00m \u001b[43mrunner\u001b[49m\u001b[43m.\u001b[49m\u001b[43mrun_get_node\u001b[49m\u001b[43m(\u001b[49m\u001b[43mprocess\u001b[49m\u001b[43m,\u001b[49m\u001b[43m \u001b[49m\u001b[43minputs\u001b[49m\u001b[43m,\u001b[49m\u001b[43m \u001b[49m\u001b[43m*\u001b[49m\u001b[43m*\u001b[49m\u001b[43mkwargs\u001b[49m\u001b[43m)\u001b[49m\n",
      "\u001b[36mFile \u001b[39m\u001b[32m~/miniforge3/envs/aiida-240/lib/python3.11/site-packages/aiida/engine/runners.py:291\u001b[39m, in \u001b[36mRunner.run_get_node\u001b[39m\u001b[34m(self, process, inputs, **kwargs)\u001b[39m\n\u001b[32m    280\u001b[39m \u001b[38;5;28;01mdef\u001b[39;00m\u001b[38;5;250m \u001b[39m\u001b[34mrun_get_node\u001b[39m(\n\u001b[32m    281\u001b[39m     \u001b[38;5;28mself\u001b[39m, process: TYPE_RUN_PROCESS, inputs: \u001b[38;5;28mdict\u001b[39m[\u001b[38;5;28mstr\u001b[39m, Any] | \u001b[38;5;28;01mNone\u001b[39;00m = \u001b[38;5;28;01mNone\u001b[39;00m, **kwargs: Any\n\u001b[32m    282\u001b[39m ) -> ResultAndNode:\n\u001b[32m    283\u001b[39m \u001b[38;5;250m    \u001b[39m\u001b[33;03m\"\"\"Run the process with the supplied inputs in this runner that will block until the process is completed.\u001b[39;00m\n\u001b[32m    284\u001b[39m \n\u001b[32m    285\u001b[39m \u001b[33;03m    The return value will be the results of the completed process\u001b[39;00m\n\u001b[32m   (...)\u001b[39m\u001b[32m    289\u001b[39m \u001b[33;03m    :return: tuple of the outputs of the process and the calculation node\u001b[39;00m\n\u001b[32m    290\u001b[39m \u001b[33;03m    \"\"\"\u001b[39;00m\n\u001b[32m--> \u001b[39m\u001b[32m291\u001b[39m     result, node = \u001b[38;5;28;43mself\u001b[39;49m\u001b[43m.\u001b[49m\u001b[43m_run\u001b[49m\u001b[43m(\u001b[49m\u001b[43mprocess\u001b[49m\u001b[43m,\u001b[49m\u001b[43m \u001b[49m\u001b[43minputs\u001b[49m\u001b[43m,\u001b[49m\u001b[43m \u001b[49m\u001b[43m*\u001b[49m\u001b[43m*\u001b[49m\u001b[43mkwargs\u001b[49m\u001b[43m)\u001b[49m\n\u001b[32m    292\u001b[39m     \u001b[38;5;28;01mreturn\u001b[39;00m ResultAndNode(result, node)\n",
      "\u001b[36mFile \u001b[39m\u001b[32m~/miniforge3/envs/aiida-240/lib/python3.11/site-packages/aiida/engine/runners.py:261\u001b[39m, in \u001b[36mRunner._run\u001b[39m\u001b[34m(self, process, inputs, **kwargs)\u001b[39m\n\u001b[32m    259\u001b[39m     signal.signal(signal.SIGINT, kill_process)\n\u001b[32m    260\u001b[39m     signal.signal(signal.SIGTERM, kill_process)\n\u001b[32m--> \u001b[39m\u001b[32m261\u001b[39m     \u001b[43mprocess_inited\u001b[49m\u001b[43m.\u001b[49m\u001b[43mexecute\u001b[49m\u001b[43m(\u001b[49m\u001b[43m)\u001b[49m\n\u001b[32m    262\u001b[39m \u001b[38;5;28;01mfinally\u001b[39;00m:\n\u001b[32m    263\u001b[39m     signal.signal(signal.SIGINT, original_handler_int)\n",
      "\u001b[36mFile \u001b[39m\u001b[32m~/miniforge3/envs/aiida-240/lib/python3.11/site-packages/plumpy/processes.py:86\u001b[39m, in \u001b[36mensure_not_closed.<locals>.func_wrapper\u001b[39m\u001b[34m(self, *args, **kwargs)\u001b[39m\n\u001b[32m     84\u001b[39m \u001b[38;5;28;01mif\u001b[39;00m \u001b[38;5;28mself\u001b[39m._closed:\n\u001b[32m     85\u001b[39m     \u001b[38;5;28;01mraise\u001b[39;00m exceptions.ClosedError(\u001b[33m'\u001b[39m\u001b[33mProcess is closed\u001b[39m\u001b[33m'\u001b[39m)\n\u001b[32m---> \u001b[39m\u001b[32m86\u001b[39m \u001b[38;5;28;01mreturn\u001b[39;00m \u001b[43mfunc\u001b[49m\u001b[43m(\u001b[49m\u001b[38;5;28;43mself\u001b[39;49m\u001b[43m,\u001b[49m\u001b[43m \u001b[49m\u001b[43m*\u001b[49m\u001b[43margs\u001b[49m\u001b[43m,\u001b[49m\u001b[43m \u001b[49m\u001b[43m*\u001b[49m\u001b[43m*\u001b[49m\u001b[43mkwargs\u001b[49m\u001b[43m)\u001b[49m\n",
      "\u001b[36mFile \u001b[39m\u001b[32m~/miniforge3/envs/aiida-240/lib/python3.11/site-packages/plumpy/processes.py:1197\u001b[39m, in \u001b[36mProcess.execute\u001b[39m\u001b[34m(self)\u001b[39m\n\u001b[32m   1194\u001b[39m \u001b[38;5;28;01mif\u001b[39;00m \u001b[38;5;129;01mnot\u001b[39;00m \u001b[38;5;28mself\u001b[39m.has_terminated():\n\u001b[32m   1195\u001b[39m     \u001b[38;5;28mself\u001b[39m.loop.run_until_complete(\u001b[38;5;28mself\u001b[39m.step_until_terminated())\n\u001b[32m-> \u001b[39m\u001b[32m1197\u001b[39m \u001b[38;5;28;01mreturn\u001b[39;00m \u001b[38;5;28;43mself\u001b[39;49m\u001b[43m.\u001b[49m\u001b[43mfuture\u001b[49m\u001b[43m(\u001b[49m\u001b[43m)\u001b[49m\u001b[43m.\u001b[49m\u001b[43mresult\u001b[49m\u001b[43m(\u001b[49m\u001b[43m)\u001b[49m\n",
      "\u001b[31mKilledError\u001b[39m: Process was killed because the runner received an interrupt"
     ]
    },
    {
     "name": "stderr",
     "output_type": "stream",
     "text": [
      "04/28/2025 03:27:55 PM <885922> aiida.engine.transports: [ERROR] Exception whilst using transport:\n",
      "Traceback (most recent call last):\n",
      "  File \"/home/ucl/modl/yimzhang/miniforge3/envs/aiida-240/lib/python3.11/site-packages/aiida/engine/transports.py\", line 106, in request_transport\n",
      "    yield transport_request.future\n",
      "  File \"/home/ucl/modl/yimzhang/miniforge3/envs/aiida-240/lib/python3.11/site-packages/aiida/engine/processes/calcjobs/tasks.py\", line 86, in do_upload\n",
      "    transport = await cancellable.with_interrupt(request)\n",
      "                ^^^^^^^^^^^^^^^^^^^^^^^^^^^^^^^^^^^^^^^^^\n",
      "  File \"/home/ucl/modl/yimzhang/miniforge3/envs/aiida-240/lib/python3.11/site-packages/aiida/engine/utils.py\", line 115, in with_interrupt\n",
      "    result = await next(wait_iter)\n",
      "             ^^^^^^^^^^^^^^^^^^^^^\n",
      "  File \"/home/ucl/modl/yimzhang/miniforge3/envs/aiida-240/lib/python3.11/asyncio/tasks.py\", line 605, in _wait_for_one\n",
      "    return f.result()  # May raise f.exception().\n",
      "           ^^^^^^^^^^\n",
      "plumpy.process_states.KillInterruption: Killed by parent<71930>\n",
      "\n",
      "04/28/2025 03:28:22 PM <885922> aiida.transport.SshTransport: [ERROR] Error connecting to proxy 'gwceci.cism.ucl.ac.be' through SSH: [SshTransport] Authentication failed., connect_args were: {'username': 'yimzhang', 'port': 22, 'look_for_keys': True, 'key_filename': '/home/ucl/modl/yimzhang/.ssh/id_rsa.ceci', 'timeout': 60, 'allow_agent': True, 'compress': True, 'gss_auth': False, 'gss_kex': False, 'gss_deleg_creds': False, 'gss_host': 'frontal.lucia.cenaero.be'}\n",
      "04/28/2025 03:28:22 PM <885922> aiida.engine.transports: [ERROR] exception occurred while trying to open transport:\n",
      " Authentication failed.\n",
      "04/28/2025 03:28:22 PM <885922> aiida.engine.transports: [ERROR] Exception whilst using transport:\n",
      "Traceback (most recent call last):\n",
      "  File \"/home/ucl/modl/yimzhang/miniforge3/envs/aiida-240/lib/python3.11/site-packages/aiida/engine/transports.py\", line 106, in request_transport\n",
      "    yield transport_request.future\n",
      "  File \"/home/ucl/modl/yimzhang/miniforge3/envs/aiida-240/lib/python3.11/site-packages/aiida/engine/processes/calcjobs/tasks.py\", line 426, in do_kill\n",
      "    transport = await cancellable.with_interrupt(request)\n",
      "                ^^^^^^^^^^^^^^^^^^^^^^^^^^^^^^^^^^^^^^^^^\n",
      "  File \"/home/ucl/modl/yimzhang/miniforge3/envs/aiida-240/lib/python3.11/site-packages/aiida/engine/utils.py\", line 115, in with_interrupt\n",
      "    result = await next(wait_iter)\n",
      "             ^^^^^^^^^^^^^^^^^^^^^\n",
      "  File \"/home/ucl/modl/yimzhang/miniforge3/envs/aiida-240/lib/python3.11/asyncio/tasks.py\", line 605, in _wait_for_one\n",
      "    return f.result()  # May raise f.exception().\n",
      "           ^^^^^^^^^^\n",
      "  File \"/home/ucl/modl/yimzhang/miniforge3/envs/aiida-240/lib/python3.11/asyncio/futures.py\", line 203, in result\n",
      "    raise self._exception.with_traceback(self._exception_tb)\n",
      "  File \"/home/ucl/modl/yimzhang/miniforge3/envs/aiida-240/lib/python3.11/site-packages/aiida/engine/transports.py\", line 87, in do_open\n",
      "    transport.open()\n",
      "  File \"/home/ucl/modl/yimzhang/miniforge3/envs/aiida-240/lib/python3.11/site-packages/aiida/transports/plugins/ssh.py\", line 480, in open\n",
      "    proxy_client.connect(proxy['host'], **proxy_connargs)\n",
      "  File \"/home/ucl/modl/yimzhang/miniforge3/envs/aiida-240/lib/python3.11/site-packages/paramiko/client.py\", line 450, in connect\n",
      "    self._auth(\n",
      "  File \"/home/ucl/modl/yimzhang/miniforge3/envs/aiida-240/lib/python3.11/site-packages/paramiko/client.py\", line 781, in _auth\n",
      "    raise saved_exception\n",
      "  File \"/home/ucl/modl/yimzhang/miniforge3/envs/aiida-240/lib/python3.11/site-packages/paramiko/client.py\", line 757, in _auth\n",
      "    self._transport.auth_publickey(username, key)\n",
      "  File \"/home/ucl/modl/yimzhang/miniforge3/envs/aiida-240/lib/python3.11/site-packages/paramiko/transport.py\", line 1635, in auth_publickey\n",
      "    return self.auth_handler.wait_for_response(my_event)\n",
      "           ^^^^^^^^^^^^^^^^^^^^^^^^^^^^^^^^^^^^^^^^^^^^^\n",
      "  File \"/home/ucl/modl/yimzhang/miniforge3/envs/aiida-240/lib/python3.11/site-packages/paramiko/auth_handler.py\", line 259, in wait_for_response\n",
      "    raise e\n",
      "paramiko.ssh_exception.AuthenticationException: Authentication failed.\n",
      "\n",
      "04/28/2025 03:28:22 PM <885922> aiida.orm.nodes.process.calculation.calcjob.CalcJobNode: [ERROR] iteration 1 of do_kill excepted, retrying after 20 seconds\n",
      "Traceback (most recent call last):\n",
      "  File \"/home/ucl/modl/yimzhang/miniforge3/envs/aiida-240/lib/python3.11/site-packages/aiida/engine/utils.py\", line 205, in exponential_backoff_retry\n",
      "    result = await coro()\n",
      "             ^^^^^^^^^^^^\n",
      "  File \"/home/ucl/modl/yimzhang/miniforge3/envs/aiida-240/lib/python3.11/site-packages/aiida/engine/processes/calcjobs/tasks.py\", line 426, in do_kill\n",
      "    transport = await cancellable.with_interrupt(request)\n",
      "                ^^^^^^^^^^^^^^^^^^^^^^^^^^^^^^^^^^^^^^^^^\n",
      "  File \"/home/ucl/modl/yimzhang/miniforge3/envs/aiida-240/lib/python3.11/site-packages/aiida/engine/utils.py\", line 115, in with_interrupt\n",
      "    result = await next(wait_iter)\n",
      "             ^^^^^^^^^^^^^^^^^^^^^\n",
      "  File \"/home/ucl/modl/yimzhang/miniforge3/envs/aiida-240/lib/python3.11/asyncio/tasks.py\", line 605, in _wait_for_one\n",
      "    return f.result()  # May raise f.exception().\n",
      "           ^^^^^^^^^^\n",
      "  File \"/home/ucl/modl/yimzhang/miniforge3/envs/aiida-240/lib/python3.11/asyncio/futures.py\", line 203, in result\n",
      "    raise self._exception.with_traceback(self._exception_tb)\n",
      "  File \"/home/ucl/modl/yimzhang/miniforge3/envs/aiida-240/lib/python3.11/site-packages/aiida/engine/transports.py\", line 87, in do_open\n",
      "    transport.open()\n",
      "  File \"/home/ucl/modl/yimzhang/miniforge3/envs/aiida-240/lib/python3.11/site-packages/aiida/transports/plugins/ssh.py\", line 480, in open\n",
      "    proxy_client.connect(proxy['host'], **proxy_connargs)\n",
      "  File \"/home/ucl/modl/yimzhang/miniforge3/envs/aiida-240/lib/python3.11/site-packages/paramiko/client.py\", line 450, in connect\n",
      "    self._auth(\n",
      "  File \"/home/ucl/modl/yimzhang/miniforge3/envs/aiida-240/lib/python3.11/site-packages/paramiko/client.py\", line 781, in _auth\n",
      "    raise saved_exception\n",
      "  File \"/home/ucl/modl/yimzhang/miniforge3/envs/aiida-240/lib/python3.11/site-packages/paramiko/client.py\", line 757, in _auth\n",
      "    self._transport.auth_publickey(username, key)\n",
      "  File \"/home/ucl/modl/yimzhang/miniforge3/envs/aiida-240/lib/python3.11/site-packages/paramiko/transport.py\", line 1635, in auth_publickey\n",
      "    return self.auth_handler.wait_for_response(my_event)\n",
      "           ^^^^^^^^^^^^^^^^^^^^^^^^^^^^^^^^^^^^^^^^^^^^^\n",
      "  File \"/home/ucl/modl/yimzhang/miniforge3/envs/aiida-240/lib/python3.11/site-packages/paramiko/auth_handler.py\", line 259, in wait_for_response\n",
      "    raise e\n",
      "paramiko.ssh_exception.AuthenticationException: Authentication failed.\n",
      "04/28/2025 03:29:13 PM <885922> aiida.engine.transports: [ERROR] Exception whilst using transport:\n",
      "Traceback (most recent call last):\n",
      "  File \"/home/ucl/modl/yimzhang/miniforge3/envs/aiida-240/lib/python3.11/site-packages/aiida/engine/transports.py\", line 106, in request_transport\n",
      "    yield transport_request.future\n",
      "  File \"/home/ucl/modl/yimzhang/miniforge3/envs/aiida-240/lib/python3.11/site-packages/aiida/engine/processes/calcjobs/tasks.py\", line 426, in do_kill\n",
      "    transport = await cancellable.with_interrupt(request)\n",
      "                ^^^^^^^^^^^^^^^^^^^^^^^^^^^^^^^^^^^^^^^^^\n",
      "  File \"/home/ucl/modl/yimzhang/miniforge3/envs/aiida-240/lib/python3.11/site-packages/aiida/engine/utils.py\", line 115, in with_interrupt\n",
      "    result = await next(wait_iter)\n",
      "             ^^^^^^^^^^^^^^^^^^^^^\n",
      "  File \"/home/ucl/modl/yimzhang/miniforge3/envs/aiida-240/lib/python3.11/asyncio/tasks.py\", line 605, in _wait_for_one\n",
      "    return f.result()  # May raise f.exception().\n",
      "           ^^^^^^^^^^\n",
      "  File \"/home/ucl/modl/yimzhang/miniforge3/envs/aiida-240/lib/python3.11/asyncio/futures.py\", line 203, in result\n",
      "    raise self._exception.with_traceback(self._exception_tb)\n",
      "  File \"/home/ucl/modl/yimzhang/miniforge3/envs/aiida-240/lib/python3.11/site-packages/aiida/engine/transports.py\", line 87, in do_open\n",
      "    transport.open()\n",
      "  File \"/home/ucl/modl/yimzhang/miniforge3/envs/aiida-240/lib/python3.11/site-packages/aiida/transports/plugins/ssh.py\", line 480, in open\n",
      "    proxy_client.connect(proxy['host'], **proxy_connargs)\n",
      "  File \"/home/ucl/modl/yimzhang/miniforge3/envs/aiida-240/lib/python3.11/site-packages/paramiko/client.py\", line 450, in connect\n",
      "    self._auth(\n",
      "  File \"/home/ucl/modl/yimzhang/miniforge3/envs/aiida-240/lib/python3.11/site-packages/paramiko/client.py\", line 781, in _auth\n",
      "    raise saved_exception\n",
      "  File \"/home/ucl/modl/yimzhang/miniforge3/envs/aiida-240/lib/python3.11/site-packages/paramiko/client.py\", line 757, in _auth\n",
      "    self._transport.auth_publickey(username, key)\n",
      "  File \"/home/ucl/modl/yimzhang/miniforge3/envs/aiida-240/lib/python3.11/site-packages/paramiko/transport.py\", line 1635, in auth_publickey\n",
      "    return self.auth_handler.wait_for_response(my_event)\n",
      "           ^^^^^^^^^^^^^^^^^^^^^^^^^^^^^^^^^^^^^^^^^^^^^\n",
      "  File \"/home/ucl/modl/yimzhang/miniforge3/envs/aiida-240/lib/python3.11/site-packages/paramiko/auth_handler.py\", line 259, in wait_for_response\n",
      "    raise e\n",
      "paramiko.ssh_exception.AuthenticationException: Authentication failed.\n",
      "\n",
      "04/28/2025 03:29:13 PM <885922> aiida.orm.nodes.process.calculation.calcjob.CalcJobNode: [ERROR] iteration 2 of do_kill excepted, retrying after 40 seconds\n",
      "Traceback (most recent call last):\n",
      "  File \"/home/ucl/modl/yimzhang/miniforge3/envs/aiida-240/lib/python3.11/site-packages/aiida/engine/utils.py\", line 205, in exponential_backoff_retry\n",
      "    result = await coro()\n",
      "             ^^^^^^^^^^^^\n",
      "  File \"/home/ucl/modl/yimzhang/miniforge3/envs/aiida-240/lib/python3.11/site-packages/aiida/engine/processes/calcjobs/tasks.py\", line 426, in do_kill\n",
      "    transport = await cancellable.with_interrupt(request)\n",
      "                ^^^^^^^^^^^^^^^^^^^^^^^^^^^^^^^^^^^^^^^^^\n",
      "  File \"/home/ucl/modl/yimzhang/miniforge3/envs/aiida-240/lib/python3.11/site-packages/aiida/engine/utils.py\", line 115, in with_interrupt\n",
      "    result = await next(wait_iter)\n",
      "             ^^^^^^^^^^^^^^^^^^^^^\n",
      "  File \"/home/ucl/modl/yimzhang/miniforge3/envs/aiida-240/lib/python3.11/asyncio/tasks.py\", line 605, in _wait_for_one\n",
      "    return f.result()  # May raise f.exception().\n",
      "           ^^^^^^^^^^\n",
      "  File \"/home/ucl/modl/yimzhang/miniforge3/envs/aiida-240/lib/python3.11/asyncio/futures.py\", line 203, in result\n",
      "    raise self._exception.with_traceback(self._exception_tb)\n",
      "  File \"/home/ucl/modl/yimzhang/miniforge3/envs/aiida-240/lib/python3.11/site-packages/aiida/engine/transports.py\", line 87, in do_open\n",
      "    transport.open()\n",
      "  File \"/home/ucl/modl/yimzhang/miniforge3/envs/aiida-240/lib/python3.11/site-packages/aiida/transports/plugins/ssh.py\", line 480, in open\n",
      "    proxy_client.connect(proxy['host'], **proxy_connargs)\n",
      "  File \"/home/ucl/modl/yimzhang/miniforge3/envs/aiida-240/lib/python3.11/site-packages/paramiko/client.py\", line 450, in connect\n",
      "    self._auth(\n",
      "  File \"/home/ucl/modl/yimzhang/miniforge3/envs/aiida-240/lib/python3.11/site-packages/paramiko/client.py\", line 781, in _auth\n",
      "    raise saved_exception\n",
      "  File \"/home/ucl/modl/yimzhang/miniforge3/envs/aiida-240/lib/python3.11/site-packages/paramiko/client.py\", line 757, in _auth\n",
      "    self._transport.auth_publickey(username, key)\n",
      "  File \"/home/ucl/modl/yimzhang/miniforge3/envs/aiida-240/lib/python3.11/site-packages/paramiko/transport.py\", line 1635, in auth_publickey\n",
      "    return self.auth_handler.wait_for_response(my_event)\n",
      "           ^^^^^^^^^^^^^^^^^^^^^^^^^^^^^^^^^^^^^^^^^^^^^\n",
      "  File \"/home/ucl/modl/yimzhang/miniforge3/envs/aiida-240/lib/python3.11/site-packages/paramiko/auth_handler.py\", line 259, in wait_for_response\n",
      "    raise e\n",
      "paramiko.ssh_exception.AuthenticationException: Authentication failed.\n",
      "04/28/2025 03:30:23 PM <885922> aiida.engine.transports: [ERROR] Exception whilst using transport:\n",
      "Traceback (most recent call last):\n",
      "  File \"/home/ucl/modl/yimzhang/miniforge3/envs/aiida-240/lib/python3.11/site-packages/aiida/engine/transports.py\", line 106, in request_transport\n",
      "    yield transport_request.future\n",
      "  File \"/home/ucl/modl/yimzhang/miniforge3/envs/aiida-240/lib/python3.11/site-packages/aiida/engine/processes/calcjobs/tasks.py\", line 426, in do_kill\n",
      "    transport = await cancellable.with_interrupt(request)\n",
      "                ^^^^^^^^^^^^^^^^^^^^^^^^^^^^^^^^^^^^^^^^^\n",
      "  File \"/home/ucl/modl/yimzhang/miniforge3/envs/aiida-240/lib/python3.11/site-packages/aiida/engine/utils.py\", line 115, in with_interrupt\n",
      "    result = await next(wait_iter)\n",
      "             ^^^^^^^^^^^^^^^^^^^^^\n",
      "  File \"/home/ucl/modl/yimzhang/miniforge3/envs/aiida-240/lib/python3.11/asyncio/tasks.py\", line 605, in _wait_for_one\n",
      "    return f.result()  # May raise f.exception().\n",
      "           ^^^^^^^^^^\n",
      "  File \"/home/ucl/modl/yimzhang/miniforge3/envs/aiida-240/lib/python3.11/asyncio/futures.py\", line 203, in result\n",
      "    raise self._exception.with_traceback(self._exception_tb)\n",
      "  File \"/home/ucl/modl/yimzhang/miniforge3/envs/aiida-240/lib/python3.11/site-packages/aiida/engine/transports.py\", line 87, in do_open\n",
      "    transport.open()\n",
      "  File \"/home/ucl/modl/yimzhang/miniforge3/envs/aiida-240/lib/python3.11/site-packages/aiida/transports/plugins/ssh.py\", line 480, in open\n",
      "    proxy_client.connect(proxy['host'], **proxy_connargs)\n",
      "  File \"/home/ucl/modl/yimzhang/miniforge3/envs/aiida-240/lib/python3.11/site-packages/paramiko/client.py\", line 450, in connect\n",
      "    self._auth(\n",
      "  File \"/home/ucl/modl/yimzhang/miniforge3/envs/aiida-240/lib/python3.11/site-packages/paramiko/client.py\", line 781, in _auth\n",
      "    raise saved_exception\n",
      "  File \"/home/ucl/modl/yimzhang/miniforge3/envs/aiida-240/lib/python3.11/site-packages/paramiko/client.py\", line 757, in _auth\n",
      "    self._transport.auth_publickey(username, key)\n",
      "  File \"/home/ucl/modl/yimzhang/miniforge3/envs/aiida-240/lib/python3.11/site-packages/paramiko/transport.py\", line 1635, in auth_publickey\n",
      "    return self.auth_handler.wait_for_response(my_event)\n",
      "           ^^^^^^^^^^^^^^^^^^^^^^^^^^^^^^^^^^^^^^^^^^^^^\n",
      "  File \"/home/ucl/modl/yimzhang/miniforge3/envs/aiida-240/lib/python3.11/site-packages/paramiko/auth_handler.py\", line 259, in wait_for_response\n",
      "    raise e\n",
      "paramiko.ssh_exception.AuthenticationException: Authentication failed.\n",
      "\n",
      "04/28/2025 03:30:23 PM <885922> aiida.orm.nodes.process.calculation.calcjob.CalcJobNode: [ERROR] iteration 3 of do_kill excepted, retrying after 80 seconds\n",
      "Traceback (most recent call last):\n",
      "  File \"/home/ucl/modl/yimzhang/miniforge3/envs/aiida-240/lib/python3.11/site-packages/aiida/engine/utils.py\", line 205, in exponential_backoff_retry\n",
      "    result = await coro()\n",
      "             ^^^^^^^^^^^^\n",
      "  File \"/home/ucl/modl/yimzhang/miniforge3/envs/aiida-240/lib/python3.11/site-packages/aiida/engine/processes/calcjobs/tasks.py\", line 426, in do_kill\n",
      "    transport = await cancellable.with_interrupt(request)\n",
      "                ^^^^^^^^^^^^^^^^^^^^^^^^^^^^^^^^^^^^^^^^^\n",
      "  File \"/home/ucl/modl/yimzhang/miniforge3/envs/aiida-240/lib/python3.11/site-packages/aiida/engine/utils.py\", line 115, in with_interrupt\n",
      "    result = await next(wait_iter)\n",
      "             ^^^^^^^^^^^^^^^^^^^^^\n",
      "  File \"/home/ucl/modl/yimzhang/miniforge3/envs/aiida-240/lib/python3.11/asyncio/tasks.py\", line 605, in _wait_for_one\n",
      "    return f.result()  # May raise f.exception().\n",
      "           ^^^^^^^^^^\n",
      "  File \"/home/ucl/modl/yimzhang/miniforge3/envs/aiida-240/lib/python3.11/asyncio/futures.py\", line 203, in result\n",
      "    raise self._exception.with_traceback(self._exception_tb)\n",
      "  File \"/home/ucl/modl/yimzhang/miniforge3/envs/aiida-240/lib/python3.11/site-packages/aiida/engine/transports.py\", line 87, in do_open\n",
      "    transport.open()\n",
      "  File \"/home/ucl/modl/yimzhang/miniforge3/envs/aiida-240/lib/python3.11/site-packages/aiida/transports/plugins/ssh.py\", line 480, in open\n",
      "    proxy_client.connect(proxy['host'], **proxy_connargs)\n",
      "  File \"/home/ucl/modl/yimzhang/miniforge3/envs/aiida-240/lib/python3.11/site-packages/paramiko/client.py\", line 450, in connect\n",
      "    self._auth(\n",
      "  File \"/home/ucl/modl/yimzhang/miniforge3/envs/aiida-240/lib/python3.11/site-packages/paramiko/client.py\", line 781, in _auth\n",
      "    raise saved_exception\n",
      "  File \"/home/ucl/modl/yimzhang/miniforge3/envs/aiida-240/lib/python3.11/site-packages/paramiko/client.py\", line 757, in _auth\n",
      "    self._transport.auth_publickey(username, key)\n",
      "  File \"/home/ucl/modl/yimzhang/miniforge3/envs/aiida-240/lib/python3.11/site-packages/paramiko/transport.py\", line 1635, in auth_publickey\n",
      "    return self.auth_handler.wait_for_response(my_event)\n",
      "           ^^^^^^^^^^^^^^^^^^^^^^^^^^^^^^^^^^^^^^^^^^^^^\n",
      "  File \"/home/ucl/modl/yimzhang/miniforge3/envs/aiida-240/lib/python3.11/site-packages/paramiko/auth_handler.py\", line 259, in wait_for_response\n",
      "    raise e\n",
      "paramiko.ssh_exception.AuthenticationException: Authentication failed.\n",
      "04/28/2025 03:32:13 PM <885922> aiida.engine.transports: [ERROR] Exception whilst using transport:\n",
      "Traceback (most recent call last):\n",
      "  File \"/home/ucl/modl/yimzhang/miniforge3/envs/aiida-240/lib/python3.11/site-packages/aiida/engine/transports.py\", line 106, in request_transport\n",
      "    yield transport_request.future\n",
      "  File \"/home/ucl/modl/yimzhang/miniforge3/envs/aiida-240/lib/python3.11/site-packages/aiida/engine/processes/calcjobs/tasks.py\", line 426, in do_kill\n",
      "    transport = await cancellable.with_interrupt(request)\n",
      "                ^^^^^^^^^^^^^^^^^^^^^^^^^^^^^^^^^^^^^^^^^\n",
      "  File \"/home/ucl/modl/yimzhang/miniforge3/envs/aiida-240/lib/python3.11/site-packages/aiida/engine/utils.py\", line 115, in with_interrupt\n",
      "    result = await next(wait_iter)\n",
      "             ^^^^^^^^^^^^^^^^^^^^^\n",
      "  File \"/home/ucl/modl/yimzhang/miniforge3/envs/aiida-240/lib/python3.11/asyncio/tasks.py\", line 605, in _wait_for_one\n",
      "    return f.result()  # May raise f.exception().\n",
      "           ^^^^^^^^^^\n",
      "  File \"/home/ucl/modl/yimzhang/miniforge3/envs/aiida-240/lib/python3.11/asyncio/futures.py\", line 203, in result\n",
      "    raise self._exception.with_traceback(self._exception_tb)\n",
      "  File \"/home/ucl/modl/yimzhang/miniforge3/envs/aiida-240/lib/python3.11/site-packages/aiida/engine/transports.py\", line 87, in do_open\n",
      "    transport.open()\n",
      "  File \"/home/ucl/modl/yimzhang/miniforge3/envs/aiida-240/lib/python3.11/site-packages/aiida/transports/plugins/ssh.py\", line 480, in open\n",
      "    proxy_client.connect(proxy['host'], **proxy_connargs)\n",
      "  File \"/home/ucl/modl/yimzhang/miniforge3/envs/aiida-240/lib/python3.11/site-packages/paramiko/client.py\", line 381, in connect\n",
      "    raise NoValidConnectionsError(errors)\n",
      "paramiko.ssh_exception.NoValidConnectionsError: [Errno None] Unable to connect to port 22 on 130.104.1.234\n",
      "\n",
      "04/28/2025 03:32:13 PM <885922> aiida.orm.nodes.process.calculation.calcjob.CalcJobNode: [ERROR] iteration 4 of do_kill excepted, retrying after 160 seconds\n",
      "Traceback (most recent call last):\n",
      "  File \"/home/ucl/modl/yimzhang/miniforge3/envs/aiida-240/lib/python3.11/site-packages/aiida/engine/utils.py\", line 205, in exponential_backoff_retry\n",
      "    result = await coro()\n",
      "             ^^^^^^^^^^^^\n",
      "  File \"/home/ucl/modl/yimzhang/miniforge3/envs/aiida-240/lib/python3.11/site-packages/aiida/engine/processes/calcjobs/tasks.py\", line 426, in do_kill\n",
      "    transport = await cancellable.with_interrupt(request)\n",
      "                ^^^^^^^^^^^^^^^^^^^^^^^^^^^^^^^^^^^^^^^^^\n",
      "  File \"/home/ucl/modl/yimzhang/miniforge3/envs/aiida-240/lib/python3.11/site-packages/aiida/engine/utils.py\", line 115, in with_interrupt\n",
      "    result = await next(wait_iter)\n",
      "             ^^^^^^^^^^^^^^^^^^^^^\n",
      "  File \"/home/ucl/modl/yimzhang/miniforge3/envs/aiida-240/lib/python3.11/asyncio/tasks.py\", line 605, in _wait_for_one\n",
      "    return f.result()  # May raise f.exception().\n",
      "           ^^^^^^^^^^\n",
      "  File \"/home/ucl/modl/yimzhang/miniforge3/envs/aiida-240/lib/python3.11/asyncio/futures.py\", line 203, in result\n",
      "    raise self._exception.with_traceback(self._exception_tb)\n",
      "  File \"/home/ucl/modl/yimzhang/miniforge3/envs/aiida-240/lib/python3.11/site-packages/aiida/engine/transports.py\", line 87, in do_open\n",
      "    transport.open()\n",
      "  File \"/home/ucl/modl/yimzhang/miniforge3/envs/aiida-240/lib/python3.11/site-packages/aiida/transports/plugins/ssh.py\", line 480, in open\n",
      "    proxy_client.connect(proxy['host'], **proxy_connargs)\n",
      "  File \"/home/ucl/modl/yimzhang/miniforge3/envs/aiida-240/lib/python3.11/site-packages/paramiko/client.py\", line 381, in connect\n",
      "    raise NoValidConnectionsError(errors)\n",
      "paramiko.ssh_exception.NoValidConnectionsError: [Errno None] Unable to connect to port 22 on 130.104.1.234\n",
      "04/28/2025 03:35:23 PM <885922> aiida.engine.transports: [ERROR] Exception whilst using transport:\n",
      "Traceback (most recent call last):\n",
      "  File \"/home/ucl/modl/yimzhang/miniforge3/envs/aiida-240/lib/python3.11/site-packages/aiida/engine/transports.py\", line 106, in request_transport\n",
      "    yield transport_request.future\n",
      "  File \"/home/ucl/modl/yimzhang/miniforge3/envs/aiida-240/lib/python3.11/site-packages/aiida/engine/processes/calcjobs/tasks.py\", line 426, in do_kill\n",
      "    transport = await cancellable.with_interrupt(request)\n",
      "                ^^^^^^^^^^^^^^^^^^^^^^^^^^^^^^^^^^^^^^^^^\n",
      "  File \"/home/ucl/modl/yimzhang/miniforge3/envs/aiida-240/lib/python3.11/site-packages/aiida/engine/utils.py\", line 115, in with_interrupt\n",
      "    result = await next(wait_iter)\n",
      "             ^^^^^^^^^^^^^^^^^^^^^\n",
      "  File \"/home/ucl/modl/yimzhang/miniforge3/envs/aiida-240/lib/python3.11/asyncio/tasks.py\", line 605, in _wait_for_one\n",
      "    return f.result()  # May raise f.exception().\n",
      "           ^^^^^^^^^^\n",
      "  File \"/home/ucl/modl/yimzhang/miniforge3/envs/aiida-240/lib/python3.11/asyncio/futures.py\", line 203, in result\n",
      "    raise self._exception.with_traceback(self._exception_tb)\n",
      "  File \"/home/ucl/modl/yimzhang/miniforge3/envs/aiida-240/lib/python3.11/site-packages/aiida/engine/transports.py\", line 87, in do_open\n",
      "    transport.open()\n",
      "  File \"/home/ucl/modl/yimzhang/miniforge3/envs/aiida-240/lib/python3.11/site-packages/aiida/transports/plugins/ssh.py\", line 480, in open\n",
      "    proxy_client.connect(proxy['host'], **proxy_connargs)\n",
      "  File \"/home/ucl/modl/yimzhang/miniforge3/envs/aiida-240/lib/python3.11/site-packages/paramiko/client.py\", line 381, in connect\n",
      "    raise NoValidConnectionsError(errors)\n",
      "paramiko.ssh_exception.NoValidConnectionsError: [Errno None] Unable to connect to port 22 on 130.104.1.234\n",
      "\n",
      "04/28/2025 03:35:23 PM <885922> aiida.orm.nodes.process.calculation.calcjob.CalcJobNode: [ERROR] iteration 5 of do_kill excepted\n",
      "Traceback (most recent call last):\n",
      "  File \"/home/ucl/modl/yimzhang/miniforge3/envs/aiida-240/lib/python3.11/site-packages/aiida/engine/utils.py\", line 205, in exponential_backoff_retry\n",
      "    result = await coro()\n",
      "             ^^^^^^^^^^^^\n",
      "  File \"/home/ucl/modl/yimzhang/miniforge3/envs/aiida-240/lib/python3.11/site-packages/aiida/engine/processes/calcjobs/tasks.py\", line 426, in do_kill\n",
      "    transport = await cancellable.with_interrupt(request)\n",
      "                ^^^^^^^^^^^^^^^^^^^^^^^^^^^^^^^^^^^^^^^^^\n",
      "  File \"/home/ucl/modl/yimzhang/miniforge3/envs/aiida-240/lib/python3.11/site-packages/aiida/engine/utils.py\", line 115, in with_interrupt\n",
      "    result = await next(wait_iter)\n",
      "             ^^^^^^^^^^^^^^^^^^^^^\n",
      "  File \"/home/ucl/modl/yimzhang/miniforge3/envs/aiida-240/lib/python3.11/asyncio/tasks.py\", line 605, in _wait_for_one\n",
      "    return f.result()  # May raise f.exception().\n",
      "           ^^^^^^^^^^\n",
      "  File \"/home/ucl/modl/yimzhang/miniforge3/envs/aiida-240/lib/python3.11/asyncio/futures.py\", line 203, in result\n",
      "    raise self._exception.with_traceback(self._exception_tb)\n",
      "  File \"/home/ucl/modl/yimzhang/miniforge3/envs/aiida-240/lib/python3.11/site-packages/aiida/engine/transports.py\", line 87, in do_open\n",
      "    transport.open()\n",
      "  File \"/home/ucl/modl/yimzhang/miniforge3/envs/aiida-240/lib/python3.11/site-packages/aiida/transports/plugins/ssh.py\", line 480, in open\n",
      "    proxy_client.connect(proxy['host'], **proxy_connargs)\n",
      "  File \"/home/ucl/modl/yimzhang/miniforge3/envs/aiida-240/lib/python3.11/site-packages/paramiko/client.py\", line 381, in connect\n",
      "    raise NoValidConnectionsError(errors)\n",
      "paramiko.ssh_exception.NoValidConnectionsError: [Errno None] Unable to connect to port 22 on 130.104.1.234\n",
      "04/28/2025 03:35:23 PM <885922> aiida.orm.nodes.process.calculation.calcjob.CalcJobNode: [WARNING] maximum attempts 5 of calling do_kill, exceeded\n",
      "04/28/2025 03:35:23 PM <885922> aiida.engine.processes.calcjobs.tasks: [WARNING] killing CalcJob<71931> failed\n",
      "04/28/2025 03:35:23 PM <885922> aiida.orm.nodes.process.calculation.calcjob.CalcJobNode: [REPORT] [71931|PwCalculation|on_except]: Traceback (most recent call last):\n",
      "  File \"/home/ucl/modl/yimzhang/miniforge3/envs/aiida-240/lib/python3.11/site-packages/aiida/engine/processes/calcjobs/tasks.py\", line 431, in task_kill_job\n",
      "    result = await exponential_backoff_retry(do_kill, initial_interval, max_attempts, logger=node.logger)\n",
      "             ^^^^^^^^^^^^^^^^^^^^^^^^^^^^^^^^^^^^^^^^^^^^^^^^^^^^^^^^^^^^^^^^^^^^^^^^^^^^^^^^^^^^^^^^^^^^\n",
      "  File \"/home/ucl/modl/yimzhang/miniforge3/envs/aiida-240/lib/python3.11/site-packages/aiida/engine/utils.py\", line 205, in exponential_backoff_retry\n",
      "    result = await coro()\n",
      "             ^^^^^^^^^^^^\n",
      "  File \"/home/ucl/modl/yimzhang/miniforge3/envs/aiida-240/lib/python3.11/site-packages/aiida/engine/processes/calcjobs/tasks.py\", line 426, in do_kill\n",
      "    transport = await cancellable.with_interrupt(request)\n",
      "                ^^^^^^^^^^^^^^^^^^^^^^^^^^^^^^^^^^^^^^^^^\n",
      "  File \"/home/ucl/modl/yimzhang/miniforge3/envs/aiida-240/lib/python3.11/site-packages/aiida/engine/utils.py\", line 115, in with_interrupt\n",
      "    result = await next(wait_iter)\n",
      "             ^^^^^^^^^^^^^^^^^^^^^\n",
      "  File \"/home/ucl/modl/yimzhang/miniforge3/envs/aiida-240/lib/python3.11/asyncio/tasks.py\", line 605, in _wait_for_one\n",
      "    return f.result()  # May raise f.exception().\n",
      "           ^^^^^^^^^^\n",
      "  File \"/home/ucl/modl/yimzhang/miniforge3/envs/aiida-240/lib/python3.11/asyncio/futures.py\", line 203, in result\n",
      "    raise self._exception.with_traceback(self._exception_tb)\n",
      "  File \"/home/ucl/modl/yimzhang/miniforge3/envs/aiida-240/lib/python3.11/site-packages/aiida/engine/transports.py\", line 87, in do_open\n",
      "    transport.open()\n",
      "  File \"/home/ucl/modl/yimzhang/miniforge3/envs/aiida-240/lib/python3.11/site-packages/aiida/transports/plugins/ssh.py\", line 480, in open\n",
      "    proxy_client.connect(proxy['host'], **proxy_connargs)\n",
      "  File \"/home/ucl/modl/yimzhang/miniforge3/envs/aiida-240/lib/python3.11/site-packages/paramiko/client.py\", line 381, in connect\n",
      "    raise NoValidConnectionsError(errors)\n",
      "paramiko.ssh_exception.NoValidConnectionsError: [Errno None] Unable to connect to port 22 on 130.104.1.234\n",
      "\n",
      "The above exception was the direct cause of the following exception:\n",
      "\n",
      "Traceback (most recent call last):\n",
      "  File \"/home/ucl/modl/yimzhang/miniforge3/envs/aiida-240/lib/python3.11/site-packages/plumpy/processes.py\", line 1218, in step\n",
      "    next_state = await self._run_task(self._state.execute)\n",
      "                 ^^^^^^^^^^^^^^^^^^^^^^^^^^^^^^^^^^^^^^^^^\n",
      "  File \"/home/ucl/modl/yimzhang/miniforge3/envs/aiida-240/lib/python3.11/site-packages/plumpy/processes.py\", line 567, in _run_task\n",
      "    result = await coro(*args, **kwargs)\n",
      "             ^^^^^^^^^^^^^^^^^^^^^^^^^^^\n",
      "  File \"/home/ucl/modl/yimzhang/miniforge3/envs/aiida-240/lib/python3.11/site-packages/aiida/engine/processes/calcjobs/tasks.py\", line 570, in execute\n",
      "    await self._kill_job(node, transport_queue)\n",
      "  File \"/home/ucl/modl/yimzhang/miniforge3/envs/aiida-240/lib/python3.11/site-packages/aiida/engine/processes/calcjobs/tasks.py\", line 623, in _launch_task\n",
      "    result = await self._task\n",
      "             ^^^^^^^^^^^^^^^^\n",
      "  File \"/home/ucl/modl/yimzhang/miniforge3/envs/aiida-240/lib/python3.11/asyncio/tasks.py\", line 339, in __wakeup\n",
      "    future.result()\n",
      "  File \"/home/ucl/modl/yimzhang/miniforge3/envs/aiida-240/lib/python3.11/site-packages/aiida/engine/utils.py\", line 137, in execute_coroutine\n",
      "    result = await coro(future)\n",
      "             ^^^^^^^^^^^^^^^^^^\n",
      "  File \"/home/ucl/modl/yimzhang/miniforge3/envs/aiida-240/lib/python3.11/site-packages/aiida/engine/processes/calcjobs/tasks.py\", line 436, in task_kill_job\n",
      "    raise TransportTaskException(f'kill_calculation failed {max_attempts} times consecutively') from exception\n",
      "aiida.common.exceptions.TransportTaskException: kill_calculation failed 5 times consecutively\n",
      "\n"
     ]
    }
   ],
   "source": [
    "inputs['skip_uc'] = orm.Bool(False)\n",
    "inputs['n_layers'] =orm.Int(8)\n",
    "inputs['slipping_system'] = orm.List(['A2', '110'])\n",
    "\n",
    "logging.getLogger('aiida.transport.SshTransport') .setLevel(logging.ERROR)\n",
    "logging.getLogger('aiida.scheduler.slurm').setLevel(logging.ERROR)\n",
    "\n",
    "test_node = run.get_node(USFWorkChain, **inputs)\n",
    "test_USF_group.add_nodes(test_node.node)"
   ]
  },
  {
   "cell_type": "markdown",
   "metadata": {},
   "source": [
    "# TEST HALF-HEUSLER"
   ]
  },
  {
   "cell_type": "code",
   "execution_count": 11,
   "metadata": {},
   "outputs": [],
   "source": [
    "\n",
    "import yaml\n",
    "\n",
    "ase_atom = read('./structures/cif/mpds-S1612207-NbCoSb-216-C1b.cif', format='cif')\n",
    "structure = orm.StructureData(ase=ase_atom)\n",
    "\n",
    "pseudo_family = orm.load_group('PseudoDojo/0.5/PBE/SR/standard/upf')\n",
    "\n",
    "pseudos = pseudo_family.get_pseudos(structure=structure)\n",
    "\n",
    "cutoff_wfc, cutoff_rho = pseudo_family.get_recommended_cutoffs(\n",
    "    structure=structure,\n",
    "    unit='Ry'\n",
    ")\n",
    "\n",
    "kpoints = orm.KpointsData()\n",
    "kpoints.set_kpoints_mesh([12, 12, 12])\n",
    "\n",
    "settings = orm.Dict({\n",
    "    # 'cmdline': ['-npool', '2']\n",
    "})\n",
    "\n",
    "usf_overrides_yaml = open('./usf.yaml')\n",
    "usf_overrides = yaml.safe_load(usf_overrides_yaml)\n",
    "\n",
    "inputs = {}\n",
    "\n",
    "inputs['metadata'] = usf_overrides.get('metadata', {})\n",
    "inputs['structure'] = structure\n",
    "inputs['kpoints'] = kpoints\n",
    "inputs['pw'] = usf_overrides.get('pw', {})\n",
    "inputs['pw']['pseudos'] = pseudos\n",
    "inputs['pw']['code'] = pw_code\n",
    "inputs['pw']['parameters']['CONTROL']['disk_io'] = 'minimal'\n",
    "inputs['pw']['parameters']['SYSTEM']['degauss'] = 0.01\n",
    "inputs['pw']['parameters']['ELECTRONS']['conv_thr'] = 1e-5\n",
    "\n"
   ]
  },
  {
   "cell_type": "markdown",
   "metadata": {},
   "source": [
    "## {100} surface"
   ]
  },
  {
   "cell_type": "code",
   "execution_count": 12,
   "metadata": {},
   "outputs": [
    {
     "name": "stderr",
     "output_type": "stream",
     "text": [
      "04/26/2025 12:11:00 PM <1225033> aiida.orm.nodes.process.workflow.workchain.WorkChainNode: [REPORT] [1137727|USFWorkChain|validate_slipping_system]: We are doing half-heusler-type structure, space group (216).\n",
      "04/26/2025 12:11:00 PM <1225033> aiida.orm.nodes.process.workflow.workchain.WorkChainNode: [REPORT] [1137727|USFWorkChain|validate_slipping_system]: AB stacking for {110} gliding plane. Faulting possible.slipping direction is along 1/2[-111].\n",
      "04/26/2025 12:11:00 PM <1225033> aiida.orm.nodes.process.workflow.workchain.WorkChainNode: [WARNING] You are skipping the unitcell calculation.Hopefully you know what you are doing!\n",
      "04/26/2025 12:11:00 PM <1225033> aiida.orm.nodes.process.workflow.workchain.WorkChainNode: [REPORT] [1137727|USFWorkChain|run_USF]: Multiplicity of the faulted geometry: uuid: 5bc1e3a8-792c-4a50-94e7-53ed01b2253d (unstored) value: 8.0\n",
      "04/26/2025 12:11:01 PM <1225033> aiida.orm.nodes.process.workflow.workchain.WorkChainNode: [REPORT] [1137727|USFWorkChain|run_USF]: launching PwCalculation<1137730> for USF geometry.\n",
      "04/26/2025 12:24:01 PM <1225033> aiida.parser.PwParser: [WARNING] key 'symmetries' is not present in raw output dictionary\n",
      "04/26/2025 12:24:01 PM <1225033> aiida.parser.PwParser: [WARNING] \"the scf_accuracy array was parsed but the scf_iterations was not.\n",
      "04/26/2025 12:24:01 PM <1225033> aiida.parser.PwParser: [ERROR] ERROR_OUTPUT_STDOUT_INCOMPLETE\n",
      "04/26/2025 12:24:01 PM <1225033> aiida.parser.PwParser: [ERROR] Both the stdout and XML output files could not be read or parsed.\n",
      "04/26/2025 12:24:01 PM <1225033> aiida.orm.nodes.process.calculation.calcjob.CalcJobNode: [WARNING] output parser returned exit code<305>: Both the stdout and XML output files could not be read or parsed.\n",
      "04/26/2025 12:24:02 PM <1225033> aiida.orm.nodes.process.workflow.workchain.WorkChainNode: [REPORT] [1137727|USFWorkChain|inspect_USF]: USF PwCalculation failed with exit status 305\n",
      "04/26/2025 12:24:02 PM <1225033> aiida.orm.nodes.process.workflow.workchain.WorkChainNode: [REPORT] [1137727|USFWorkChain|on_terminated]: remote folders will not be cleaned\n"
     ]
    }
   ],
   "source": [
    "inputs['skip_uc'] = orm.Bool(True)\n",
    "inputs['n_layers'] =orm.Int(8)\n",
    "inputs['slipping_system'] = orm.List(['C1b', '110', None])\n",
    "\n",
    "logging.getLogger('aiida.transport.SshTransport').setLevel(logging.ERROR)\n",
    "logging.getLogger('aiida.scheduler.slurm').setLevel(logging.ERROR)\n",
    "\n",
    "test_node = run.get_node(USFWorkChain, **inputs)"
   ]
  },
  {
   "cell_type": "code",
   "execution_count": null,
   "metadata": {},
   "outputs": [],
   "source": []
  }
 ],
 "metadata": {
  "kernelspec": {
   "display_name": "aiida-240",
   "language": "python",
   "name": "python3"
  },
  "language_info": {
   "codemirror_mode": {
    "name": "ipython",
    "version": 3
   },
   "file_extension": ".py",
   "mimetype": "text/x-python",
   "name": "python",
   "nbconvert_exporter": "python",
   "pygments_lexer": "ipython3",
   "version": "3.11.0"
  }
 },
 "nbformat": 4,
 "nbformat_minor": 2
}
